File: winhausen_data/OPA-Z45-10MPa_OPA23.txt
"time [h]"	"axial strain[%]"	"radial strain[%]"	"diff. stress[MPa]"	"eff. mean stress[MPa]"	"mean u[MPa]"
0.00	0.00	0.00	0.01	10.02	2.80
0.03	0.00	0.00	0.02	10.01	2.80
0.06	0.00	0.00	0.04	10.02	2.80
0.08	0.00	0.00	0.08	10.03	2.80
0.11	0.00	0.00	0.13	10.02	2.82
0.14	0.00	0.00	0.17	10.04	2.82
0.17	0.00	0.00	0.22	10.04	2.84
0.19	0.00	0.00	0.27	10.04	2.85
0.22	0.00	0.00	0.31	10.06	2.84
0.25	0.01	0.00	0.36	10.07	2.85
0.28	0.01	-0.01	0.40	10.07	2.87
0.31	0.01	-0.01	0.44	10.06	2.89
0.33	0.01	-0.01	0.49	10.08	2.88
0.36	0.01	-0.01	0.53	10.08	2.89
0.39	0.01	-0.01	0.57	10.08	2.91
0.42	0.01	-0.01	0.61	10.09	2.92
0.44	0.01	-0.01	0.66	10.09	2.93
0.47	0.01	-0.01	0.70	10.09	2.94
0.50	0.01	-0.01	0.74	10.09	2.95
0.53	0.02	-0.01	0.78	10.08	2.97
0.56	0.02	-0.01	0.82	10.10	2.97
0.58	0.02	-0.01	0.85	10.13	2.96
0.61	0.02	-0.01	0.89	10.11	2.99
0.64	0.02	-0.01	0.93	10.11	3.00
0.67	0.02	-0.01	0.97	10.10	3.02
0.69	0.02	-0.01	1.01	10.09	3.05
0.72	0.02	-0.01	1.04	10.10	3.04
0.75	0.02	-0.02	1.08	10.10	3.06
0.78	0.02	-0.02	1.11	10.10	3.08
0.81	0.03	-0.02	1.15	10.10	3.08
0.83	0.03	-0.02	1.18	10.11	3.08
0.86	0.03	-0.02	1.22	10.10	3.10
0.89	0.03	-0.02	1.25	10.10	3.12
0.92	0.03	-0.02	1.28	10.10	3.13
0.94	0.03	-0.02	1.32	10.10	3.14
0.97	0.03	-0.02	1.35	10.10	3.15
1.00	0.03	-0.02	1.38	10.09	3.17
1.03	0.03	-0.02	1.42	10.12	3.15
1.06	0.03	-0.02	1.45	10.13	3.16
1.08	0.04	-0.02	1.48	10.10	3.20
1.11	0.04	-0.02	1.51	10.09	3.21
1.14	0.04	-0.02	1.55	10.11	3.21
1.17	0.04	-0.02	1.58	10.10	3.23
1.19	0.04	-0.02	1.61	10.10	3.23
1.22	0.04	-0.03	1.64	10.11	3.24
1.25	0.04	-0.03	1.67	10.10	3.26
1.28	0.04	-0.03	1.70	10.10	3.26
1.31	0.04	-0.03	1.73	10.09	3.28
1.33	0.04	-0.03	1.76	10.08	3.31
1.36	0.05	-0.03	1.79	10.10	3.30
1.39	0.05	-0.03	1.81	10.08	3.32
1.42	0.05	-0.03	1.84	10.08	3.34
1.44	0.05	-0.03	1.87	10.09	3.33
1.47	0.05	-0.03	1.90	10.08	3.35
1.50	0.05	-0.03	1.93	10.08	3.37
1.53	0.05	-0.03	1.96	10.07	3.38
1.56	0.05	-0.03	1.99	10.08	3.39
1.58	0.05	-0.03	2.02	10.07	3.40
1.61	0.05	-0.03	2.04	10.06	3.42
1.64	0.06	-0.03	2.07	10.06	3.43
1.67	0.06	-0.04	2.10	10.06	3.44
1.69	0.06	-0.04	2.14	10.06	3.45
1.72	0.06	-0.04	2.15	10.07	3.45
1.75	0.06	-0.04	2.18	10.05	3.47
1.78	0.06	-0.04	2.21	10.05	3.49
1.81	0.06	-0.04	2.23	10.04	3.50
1.83	0.06	-0.04	2.26	10.05	3.50
1.86	0.06	-0.04	2.29	10.05	3.51
1.89	0.06	-0.04	2.31	10.04	3.53
1.92	0.07	-0.04	2.33	10.04	3.54
1.94	0.07	-0.04	2.36	10.04	3.55
1.97	0.07	-0.04	2.38	10.04	3.55
2.00	0.07	-0.04	2.41	10.04	3.57
2.03	0.07	-0.04	2.44	10.03	3.58
2.06	0.07	-0.04	2.46	10.03	3.59
2.08	0.07	-0.04	2.48	10.04	3.58
2.11	0.07	-0.05	2.51	10.05	3.58
2.14	0.07	-0.05	2.53	10.04	3.60
2.17	0.07	-0.05	2.55	10.04	3.61
2.19	0.08	-0.05	2.58	10.03	3.63
2.22	0.08	-0.05	2.60	10.03	3.64
2.25	0.08	-0.05	2.63	10.03	3.64
2.28	0.08	-0.05	2.65	10.03	3.66
2.31	0.08	-0.05	2.67	10.02	3.67
2.33	0.08	-0.05	2.71	10.04	3.66
2.36	0.08	-0.05	2.72	10.05	3.66
2.39	0.08	-0.05	2.74	10.01	3.71
2.42	0.08	-0.05	2.76	10.03	3.70
2.44	0.08	-0.05	2.79	10.02	3.71
2.47	0.09	-0.05	2.81	10.02	3.71
2.50	0.09	-0.05	2.83	10.04	3.71
2.53	0.09	-0.05	2.85	10.02	3.73
2.56	0.09	-0.06	2.88	10.03	3.73
2.58	0.09	-0.06	2.90	10.01	3.75
2.61	0.09	-0.06	2.92	10.00	3.77
2.64	0.09	-0.06	2.94	10.00	3.78
2.67	0.09	-0.06	2.96	10.02	3.76
2.69	0.09	-0.06	2.99	9.99	3.81
2.72	0.10	-0.06	3.01	10.01	3.79
2.75	0.10	-0.06	3.03	10.02	3.79
2.78	0.10	-0.06	3.05	10.00	3.82
2.81	0.10	-0.06	3.07	9.99	3.83
2.83	0.10	-0.06	3.09	10.00	3.83
2.86	0.10	-0.06	3.11	9.99	3.85
2.89	0.10	-0.06	3.13	9.98	3.86
2.92	0.10	-0.06	3.16	9.99	3.87
2.94	0.10	-0.06	3.17	9.98	3.88
2.97	0.10	-0.06	3.20	10.00	3.87
3.00	0.11	-0.07	3.22	9.98	3.89
3.03	0.11	-0.07	3.24	9.98	3.90
3.06	0.11	-0.07	3.26	9.97	3.91
3.08	0.11	-0.07	3.28	9.98	3.91
3.11	0.11	-0.07	3.30	9.98	3.92
3.14	0.11	-0.07	3.32	9.97	3.93
3.17	0.11	-0.07	3.34	9.97	3.94
3.19	0.11	-0.07	3.36	9.98	3.94
3.22	0.11	-0.07	3.38	9.98	3.95
3.25	0.11	-0.07	3.40	9.99	3.94
3.28	0.12	-0.07	3.42	9.96	3.98
3.31	0.12	-0.07	3.44	9.97	3.98
3.33	0.12	-0.07	3.46	9.97	3.98
3.36	0.12	-0.07	3.48	9.96	3.99
3.39	0.12	-0.07	3.49	9.96	4.00
3.42	0.12	-0.08	3.52	9.96	4.01
3.44	0.12	-0.08	3.53	9.97	4.01
3.47	0.12	-0.08	3.55	9.95	4.03
3.50	0.12	-0.08	3.58	9.96	4.03
3.53	0.12	-0.08	3.59	9.96	4.04
3.56	0.13	-0.08	3.61	9.96	4.05
3.58	0.13	-0.08	3.63	9.96	4.05
3.61	0.13	-0.08	3.65	9.95	4.07
3.64	0.13	-0.08	3.67	9.94	4.08
3.67	0.13	-0.08	3.69	9.94	4.09
3.69	0.13	-0.08	3.70	9.94	4.09
3.72	0.13	-0.08	3.73	9.94	4.11
3.75	0.13	-0.08	3.75	9.93	4.11
3.78	0.13	-0.08	3.76	9.94	4.11
3.81	0.13	-0.08	3.78	9.93	4.13
3.83	0.14	-0.08	3.80	9.93	4.13
3.86	0.14	-0.09	3.82	9.94	4.14
3.89	0.14	-0.09	3.84	9.93	4.15
3.92	0.14	-0.09	3.86	9.95	4.14
3.94	0.14	-0.09	3.87	9.93	4.16
3.97	0.14	-0.09	3.89	9.94	4.16
4.00	0.14	-0.09	3.91	9.92	4.18
4.03	0.14	-0.09	3.93	9.92	4.19
4.06	0.14	-0.09	3.95	9.93	4.19
4.08	0.14	-0.09	3.96	9.94	4.18
4.11	0.15	-0.09	3.98	9.91	4.21
4.14	0.15	-0.09	4.00	9.91	4.23
4.17	0.15	-0.09	4.02	9.91	4.23
4.19	0.15	-0.09	4.04	9.90	4.24
4.22	0.15	-0.09	4.06	9.90	4.25
4.25	0.15	-0.09	4.07	9.90	4.25
4.28	0.15	-0.10	4.09	9.91	4.26
4.31	0.15	-0.10	4.11	9.91	4.26
4.33	0.15	-0.10	4.13	9.91	4.26
4.36	0.15	-0.10	4.14	9.91	4.27
4.39	0.16	-0.10	4.16	9.94	4.25
4.42	0.16	-0.10	4.18	9.92	4.28
4.44	0.16	-0.10	4.20	9.91	4.29
4.47	0.16	-0.10	4.21	9.90	4.31
4.50	0.16	-0.10	4.23	9.91	4.30
4.53	0.16	-0.10	4.25	9.90	4.32
4.56	0.16	-0.10	4.26	9.88	4.34
4.58	0.16	-0.10	4.28	9.90	4.33
4.61	0.16	-0.10	4.30	9.90	4.33
4.64	0.16	-0.10	4.32	9.88	4.35
4.67	0.17	-0.10	4.33	9.88	4.36
4.69	0.17	-0.11	4.35	9.88	4.38
4.72	0.17	-0.11	4.37	9.89	4.36
4.75	0.17	-0.11	4.38	9.89	4.37
4.78	0.17	-0.11	4.40	9.87	4.39
4.81	0.17	-0.11	4.42	9.88	4.39
4.83	0.17	-0.11	4.43	9.88	4.39
4.86	0.17	-0.11	4.45	9.87	4.41
4.89	0.17	-0.11	4.47	9.88	4.41
4.92	0.17	-0.11	4.48	9.87	4.42
4.94	0.18	-0.11	4.50	9.88	4.42
4.97	0.18	-0.11	4.52	9.86	4.45
5.00	0.18	-0.11	4.53	9.88	4.43
5.03	0.18	-0.11	4.55	9.87	4.45
5.06	0.18	-0.11	4.57	9.86	4.47
5.08	0.18	-0.11	4.58	9.86	4.47
5.11	0.18	-0.11	4.60	9.87	4.47
5.14	0.18	-0.12	4.62	9.85	4.49
5.17	0.18	-0.12	4.63	9.86	4.48
5.19	0.18	-0.12	4.65	9.85	4.50
5.22	0.19	-0.12	4.66	9.85	4.51
5.25	0.19	-0.12	4.68	9.86	4.50
5.28	0.19	-0.12	4.70	9.85	4.51
5.31	0.19	-0.12	4.71	9.89	4.48
5.33	0.19	-0.12	4.73	9.84	4.54
5.36	0.19	-0.12	4.75	9.85	4.53
5.39	0.19	-0.12	4.76	9.86	4.52
5.42	0.19	-0.12	4.78	9.87	4.52
5.44	0.19	-0.12	4.80	9.87	4.53
5.47	0.19	-0.12	4.81	9.84	4.57
5.50	0.20	-0.12	4.83	9.83	4.58
5.53	0.20	-0.12	4.84	9.83	4.58
5.56	0.20	-0.13	4.86	9.82	4.60
5.58	0.20	-0.13	4.87	9.83	4.60
5.61	0.20	-0.13	4.89	9.83	4.60
5.64	0.20	-0.13	4.91	9.82	4.61
5.67	0.20	-0.13	4.92	9.82	4.62
5.69	0.20	-0.13	4.94	9.81	4.63
5.72	0.20	-0.13	4.95	9.83	4.62
5.75	0.20	-0.13	4.97	9.82	4.64
5.78	0.21	-0.13	4.98	9.81	4.65
5.81	0.21	-0.13	5.00	9.81	4.66
5.83	0.21	-0.13	5.02	9.82	4.65
5.86	0.21	-0.13	5.03	9.82	4.65
5.89	0.21	-0.13	5.05	9.80	4.68
5.92	0.21	-0.13	5.07	9.81	4.68
5.94	0.21	-0.13	5.08	9.83	4.67
5.97	0.21	-0.14	5.10	9.83	4.67
6.00	0.21	-0.14	5.11	9.82	4.69
6.03	0.22	-0.14	5.13	9.82	4.69
6.06	0.22	-0.14	5.14	9.81	4.70
6.08	0.22	-0.14	5.15	9.81	4.71
6.11	0.22	-0.14	5.17	9.80	4.72
6.14	0.22	-0.14	5.19	9.81	4.72
6.17	0.22	-0.14	5.20	9.80	4.73
6.19	0.22	-0.14	5.22	9.81	4.73
6.22	0.22	-0.14	5.23	9.80	4.74
6.25	0.22	-0.14	5.25	9.81	4.74
6.28	0.22	-0.14	5.26	9.81	4.75
6.31	0.23	-0.14	5.28	9.80	4.75
6.33	0.23	-0.14	5.30	9.80	4.77
6.36	0.23	-0.14	5.31	9.80	4.77
6.39	0.23	-0.15	5.32	9.79	4.79
6.42	0.23	-0.15	5.34	9.79	4.79
6.44	0.23	-0.15	5.36	9.80	4.79
6.47	0.23	-0.15	5.37	9.78	4.81
6.50	0.23	-0.15	5.39	9.81	4.79
6.53	0.23	-0.15	5.40	9.80	4.80
6.56	0.23	-0.15	5.41	9.80	4.81
6.58	0.24	-0.15	5.43	9.80	4.81
6.61	0.24	-0.15	5.44	9.79	4.82
6.64	0.24	-0.15	5.46	9.79	4.83
6.67	0.24	-0.15	5.47	9.79	4.83
6.69	0.24	-0.15	5.49	9.79	4.84
6.72	0.24	-0.15	5.51	9.78	4.85
6.75	0.24	-0.15	5.52	9.79	4.85
6.78	0.24	-0.15	5.53	9.79	4.86
6.81	0.24	-0.16	5.55	9.79	4.86
6.83	0.24	-0.16	5.56	9.79	4.87
6.86	0.25	-0.16	5.58	9.79	4.87
6.89	0.25	-0.16	5.59	9.78	4.89
6.92	0.25	-0.16	5.60	9.77	4.90
6.94	0.25	-0.16	5.62	9.78	4.89
6.97	0.25	-0.16	5.64	9.78	4.90
7.00	0.25	-0.16	5.65	9.78	4.91
7.03	0.25	-0.16	5.67	9.77	4.92
7.06	0.25	-0.16	5.68	9.77	4.93
7.08	0.25	-0.16	5.69	9.78	4.91
7.11	0.25	-0.16	5.71	9.78	4.92
7.14	0.26	-0.16	5.72	9.77	4.94
7.17	0.26	-0.16	5.74	9.78	4.94
7.19	0.26	-0.16	5.75	9.77	4.95
7.22	0.26	-0.17	5.76	9.77	4.95
7.25	0.26	-0.17	5.78	9.77	4.96
7.28	0.26	-0.17	5.79	9.77	4.96
7.31	0.26	-0.17	5.81	9.75	4.98
7.33	0.26	-0.17	5.82	9.76	4.98
7.36	0.26	-0.17	5.84	9.77	4.98
7.39	0.26	-0.17	5.85	9.77	4.99
7.42	0.27	-0.17	5.87	9.77	4.99
7.44	0.27	-0.17	5.88	9.76	5.00
7.47	0.27	-0.17	5.89	9.75	5.01
7.50	0.27	-0.17	5.91	9.76	5.01
7.53	0.27	-0.17	5.92	9.75	5.02
7.56	0.27	-0.17	5.94	9.76	5.02
7.58	0.27	-0.17	5.95	9.76	5.03
7.61	0.27	-0.18	5.97	9.77	5.02
7.64	0.27	-0.18	5.98	9.75	5.04
7.67	0.27	-0.18	5.99	9.75	5.05
7.69	0.28	-0.18	6.00	9.74	5.06
7.72	0.28	-0.18	6.02	9.78	5.03
7.75	0.28	-0.18	6.04	9.76	5.05
7.78	0.28	-0.18	6.05	9.74	5.08
7.81	0.28	-0.18	6.06	9.76	5.07
7.83	0.28	-0.18	6.08	9.76	5.07
7.86	0.28	-0.18	6.09	9.75	5.08
7.89	0.28	-0.18	6.10	9.78	5.06
7.92	0.28	-0.18	6.12	9.74	5.10
7.94	0.28	-0.18	6.13	9.74	5.10
7.97	0.29	-0.18	6.14	9.74	5.11
8.00	0.29	-0.18	6.16	9.74	5.12
8.03	0.29	-0.19	6.17	9.73	5.13
8.06	0.29	-0.19	6.19	9.73	5.13
8.08	0.29	-0.19	6.20	9.73	5.13
8.11	0.29	-0.19	6.22	9.74	5.13
8.14	0.29	-0.19	6.23	9.73	5.14
8.17	0.29	-0.19	6.24	9.73	5.15
8.19	0.29	-0.19	6.25	9.74	5.15
8.22	0.29	-0.19	6.27	9.73	5.15
8.25	0.30	-0.19	6.28	9.73	5.17
8.28	0.30	-0.19	6.29	9.71	5.19
8.31	0.30	-0.19	6.31	9.74	5.17
8.33	0.30	-0.19	6.32	9.74	5.17
8.36	0.30	-0.19	6.34	9.75	5.17
8.39	0.30	-0.19	6.35	9.74	5.17
8.42	0.30	-0.20	6.37	9.72	5.20
8.44	0.30	-0.20	6.38	9.73	5.20
8.47	0.30	-0.20	6.39	9.73	5.20
8.50	0.30	-0.20	6.40	9.73	5.21
8.53	0.31	-0.20	6.42	9.72	5.21
8.56	0.31	-0.20	6.43	9.73	5.21
8.58	0.31	-0.20	6.44	9.72	5.23
8.61	0.31	-0.20	6.46	9.71	5.24
8.64	0.31	-0.20	6.47	9.73	5.23
8.67	0.31	-0.20	6.49	9.73	5.24
8.69	0.31	-0.20	6.50	9.72	5.25
8.72	0.31	-0.20	6.51	9.71	5.26
8.75	0.31	-0.20	6.53	9.72	5.26
8.78	0.31	-0.20	6.54	9.72	5.26
8.81	0.32	-0.20	6.55	9.71	5.27
8.83	0.32	-0.21	6.56	9.72	5.26
8.86	0.32	-0.21	6.58	9.72	5.27
8.89	0.32	-0.21	6.59	9.72	5.28
8.92	0.32	-0.21	6.60	9.71	5.29
8.94	0.32	-0.21	6.62	9.71	5.29
8.97	0.32	-0.21	6.63	9.72	5.29
9.00	0.32	-0.21	6.64	9.72	5.29
9.03	0.32	-0.21	6.66	9.71	5.31
9.06	0.32	-0.21	6.67	9.71	5.32
9.08	0.33	-0.21	6.68	9.71	5.32
9.11	0.33	-0.21	6.70	9.71	5.32
9.14	0.33	-0.21	6.71	9.71	5.32
9.17	0.33	-0.21	6.72	9.71	5.33
9.19	0.33	-0.21	6.73	9.70	5.34
9.22	0.33	-0.21	6.75	9.71	5.34
9.25	0.33	-0.22	6.76	9.71	5.34
9.28	0.33	-0.22	6.78	9.71	5.35
9.31	0.33	-0.22	6.79	9.70	5.36
9.33	0.34	-0.22	6.80	9.71	5.36
9.36	0.34	-0.22	6.81	9.71	5.36
9.39	0.34	-0.22	6.83	9.70	5.37
9.42	0.34	-0.22	6.84	9.70	5.38
9.44	0.34	-0.22	6.85	9.71	5.38
9.47	0.34	-0.22	6.87	9.71	5.38
9.50	0.34	-0.22	6.88	9.70	5.39
9.53	0.34	-0.22	6.89	9.69	5.41
9.56	0.34	-0.22	6.90	9.71	5.39
9.58	0.34	-0.22	6.92	9.71	5.40
9.61	0.35	-0.22	6.93	9.70	5.41
9.64	0.35	-0.23	6.94	9.70	5.41
9.67	0.35	-0.23	6.96	9.69	5.43
9.69	0.35	-0.23	6.97	9.70	5.43
9.72	0.35	-0.23	6.98	9.70	5.43
9.75	0.35	-0.23	6.99	9.70	5.43
9.78	0.35	-0.23	7.01	9.69	5.45
9.81	0.35	-0.23	7.02	9.70	5.44
9.83	0.35	-0.23	7.03	9.69	5.45
9.86	0.35	-0.23	7.04	9.69	5.46
9.89	0.36	-0.23	7.05	9.69	5.46
9.92	0.36	-0.23	7.07	9.69	5.47
9.94	0.36	-0.23	7.08	9.69	5.47
9.97	0.36	-0.23	7.09	9.69	5.48
10.00	0.36	-0.23	7.11	9.69	5.48
10.03	0.36	-0.24	7.12	9.68	5.49
10.06	0.36	-0.24	7.13	9.68	5.50
10.08	0.36	-0.24	7.14	9.69	5.49
10.11	0.36	-0.24	7.16	9.69	5.50
10.14	0.36	-0.24	7.17	9.67	5.52
10.17	0.37	-0.24	7.18	9.68	5.51
10.19	0.37	-0.24	7.19	9.69	5.51
10.22	0.37	-0.24	7.21	9.69	5.51
10.25	0.37	-0.24	7.22	9.68	5.52
10.28	0.37	-0.24	7.23	9.68	5.53
10.31	0.37	-0.24	7.24	9.68	5.54
10.33	0.37	-0.24	7.25	9.68	5.54
10.36	0.37	-0.24	7.27	9.68	5.54
10.39	0.37	-0.24	7.28	9.68	5.55
10.42	0.37	-0.24	7.29	9.67	5.56
10.44	0.38	-0.25	7.30	9.69	5.55
10.47	0.38	-0.25	7.32	9.68	5.56
10.50	0.38	-0.25	7.33	9.67	5.57
10.53	0.38	-0.25	7.34	9.68	5.57
10.56	0.38	-0.25	7.35	9.69	5.56
10.58	0.38	-0.25	7.36	9.71	5.54
10.61	0.38	-0.25	7.37	9.71	5.55
10.64	0.38	-0.25	7.39	9.68	5.58
10.67	0.38	-0.25	7.40	9.69	5.58
10.69	0.38	-0.25	7.41	9.68	5.59
10.72	0.39	-0.25	7.42	9.72	5.56
10.75	0.39	-0.25	7.43	9.67	5.61
10.78	0.39	-0.25	7.45	9.67	5.62
10.81	0.39	-0.25	7.46	9.70	5.59
10.83	0.39	-0.26	7.47	9.68	5.61
10.86	0.39	-0.26	7.48	9.67	5.62
10.89	0.39	-0.26	7.49	9.68	5.62
10.92	0.39	-0.26	7.51	9.69	5.61
10.94	0.39	-0.26	7.52	9.67	5.64
10.97	0.39	-0.26	7.53	9.67	5.64
11.00	0.40	-0.26	7.54	9.67	5.64
11.03	0.40	-0.26	7.56	9.68	5.64
11.06	0.40	-0.26	7.57	9.67	5.65
11.08	0.40	-0.26	7.58	9.66	5.67
11.11	0.40	-0.26	7.59	9.67	5.66
11.14	0.40	-0.26	7.60	9.68	5.66
11.17	0.40	-0.26	7.61	9.67	5.66
11.19	0.40	-0.26	7.63	9.67	5.67
11.22	0.40	-0.27	7.64	9.68	5.67
11.25	0.40	-0.27	7.65	9.68	5.67
11.28	0.41	-0.27	7.66	9.68	5.67
11.31	0.41	-0.27	7.67	9.67	5.69
11.33	0.41	-0.27	7.69	9.67	5.69
11.36	0.41	-0.27	7.69	9.66	5.70
11.39	0.41	-0.27	7.71	9.66	5.71
11.42	0.41	-0.27	7.72	9.67	5.71
11.44	0.41	-0.27	7.73	9.67	5.71
11.47	0.41	-0.27	7.74	9.67	5.71
11.50	0.41	-0.27	7.76	9.67	5.71
11.53	0.41	-0.27	7.77	9.67	5.72
11.56	0.42	-0.27	7.78	9.68	5.71
11.58	0.42	-0.27	7.79	9.66	5.74
11.61	0.42	-0.28	7.80	9.67	5.73
11.64	0.42	-0.28	7.81	9.68	5.72
11.67	0.42	-0.28	7.83	9.67	5.74
11.69	0.42	-0.28	7.84	9.67	5.75
11.72	0.42	-0.28	7.85	9.66	5.76
11.75	0.42	-0.28	7.86	9.67	5.75
11.78	0.42	-0.28	7.87	9.68	5.75
11.81	0.42	-0.28	7.88	9.67	5.76
11.83	0.43	-0.28	7.89	9.66	5.77
11.86	0.43	-0.28	7.90	9.68	5.76
11.89	0.43	-0.28	7.92	9.67	5.77
11.92	0.43	-0.28	7.93	9.67	5.78
11.94	0.43	-0.28	7.94	9.66	5.79
11.97	0.43	-0.28	7.95	9.67	5.78
12.00	0.43	-0.29	7.96	9.66	5.79
12.03	0.43	-0.29	7.97	9.68	5.78
12.06	0.43	-0.29	7.99	9.67	5.80
12.08	0.43	-0.29	8.00	9.67	5.80
12.11	0.44	-0.29	8.01	9.68	5.79
12.14	0.44	-0.29	8.02	9.68	5.79
12.17	0.44	-0.29	8.03	9.68	5.80
12.19	0.44	-0.29	8.04	9.67	5.81
12.22	0.44	-0.29	8.05	9.66	5.82
12.25	0.44	-0.29	8.06	9.66	5.82
12.28	0.44	-0.29	8.08	9.67	5.82
12.31	0.44	-0.29	8.09	9.66	5.83
12.33	0.44	-0.29	8.10	9.68	5.82
12.36	0.44	-0.29	8.11	9.66	5.84
12.39	0.45	-0.30	8.12	9.70	5.81
12.42	0.45	-0.30	8.13	9.71	5.80
12.44	0.45	-0.30	8.14	9.66	5.86
12.47	0.45	-0.30	8.15	9.67	5.85
12.50	0.45	-0.30	8.17	9.67	5.85
12.53	0.45	-0.30	8.18	9.67	5.86
12.56	0.45	-0.30	8.19	9.70	5.83
12.58	0.45	-0.30	8.20	9.67	5.86
12.61	0.45	-0.30	8.21	9.66	5.87
12.64	0.46	-0.30	8.22	9.66	5.88
12.67	0.46	-0.30	8.23	9.65	5.89
12.69	0.46	-0.30	8.24	9.66	5.89
12.72	0.46	-0.30	8.25	9.67	5.88
12.75	0.46	-0.30	8.26	9.65	5.91
12.78	0.46	-0.31	8.27	9.66	5.89
12.81	0.46	-0.31	8.29	9.68	5.88
12.83	0.46	-0.31	8.30	9.67	5.90
12.86	0.46	-0.31	8.31	9.68	5.88
12.89	0.46	-0.31	8.32	9.65	5.92
12.92	0.47	-0.31	8.33	9.70	5.88
12.94	0.47	-0.31	8.34	9.65	5.93
12.97	0.47	-0.31	8.35	9.66	5.93
13.00	0.47	-0.31	8.36	9.66	5.92
13.03	0.47	-0.31	8.38	9.67	5.92
13.06	0.47	-0.31	8.39	9.66	5.94
13.08	0.47	-0.31	8.40	9.66	5.94
13.11	0.47	-0.31	8.41	9.68	5.93
13.14	0.47	-0.31	8.42	9.68	5.93
13.17	0.47	-0.32	8.43	9.68	5.93
13.19	0.48	-0.32	8.44	9.67	5.95
13.22	0.48	-0.32	8.45	9.65	5.96
13.25	0.48	-0.32	8.46	9.68	5.94
13.28	0.48	-0.32	8.47	9.68	5.95
13.31	0.48	-0.32	8.48	9.65	5.97
13.33	0.48	-0.32	8.49	9.65	5.98
13.36	0.48	-0.32	8.50	9.67	5.97
13.39	0.48	-0.32	8.51	9.67	5.96
13.42	0.48	-0.32	8.52	9.67	5.97
13.44	0.48	-0.32	8.53	9.67	5.98
13.47	0.49	-0.32	8.55	9.67	5.98
13.50	0.49	-0.32	8.56	9.66	5.99
13.53	0.49	-0.32	8.57	9.66	5.99
13.56	0.49	-0.33	8.58	9.67	5.98
13.58	0.49	-0.33	8.59	9.67	5.99
13.61	0.49	-0.33	8.60	9.67	5.99
13.64	0.49	-0.33	8.61	9.67	6.00
13.67	0.49	-0.33	8.62	9.66	6.01
13.69	0.49	-0.33	8.63	9.68	6.00
13.72	0.49	-0.33	8.64	9.68	6.00
13.75	0.50	-0.33	8.65	9.67	6.01
13.78	0.50	-0.33	8.66	9.66	6.03
13.81	0.50	-0.33	8.67	9.66	6.03
13.83	0.50	-0.33	8.68	9.67	6.02
13.86	0.50	-0.33	8.69	9.67	6.03
13.89	0.50	-0.33	8.70	9.67	6.03
13.92	0.50	-0.34	8.71	9.67	6.03
13.94	0.50	-0.34	8.72	9.67	6.04
13.97	0.50	-0.34	8.74	9.68	6.03
14.00	0.50	-0.34	8.74	9.68	6.03
14.03	0.51	-0.34	8.76	9.67	6.05
14.06	0.51	-0.34	8.76	9.68	6.04
14.08	0.51	-0.34	8.78	9.67	6.06
14.11	0.51	-0.34	8.79	9.67	6.06
14.14	0.51	-0.34	8.80	9.67	6.06
14.17	0.51	-0.34	8.81	9.68	6.06
14.19	0.51	-0.34	8.82	9.67	6.07
14.22	0.51	-0.34	8.83	9.67	6.07
14.25	0.51	-0.34	8.84	9.67	6.08
14.28	0.51	-0.34	8.85	9.66	6.09
14.31	0.52	-0.35	8.86	9.68	6.07
14.33	0.52	-0.35	8.87	9.68	6.08
14.36	0.52	-0.35	8.88	9.66	6.10
14.39	0.52	-0.35	8.89	9.67	6.10
14.42	0.52	-0.35	8.90	9.67	6.09
14.44	0.52	-0.35	8.91	9.68	6.09
14.47	0.52	-0.35	8.92	9.68	6.10
14.50	0.52	-0.35	8.93	9.69	6.08
14.53	0.52	-0.35	8.94	9.69	6.09
14.56	0.52	-0.35	8.95	9.69	6.10
14.58	0.53	-0.35	8.96	9.68	6.10
14.61	0.53	-0.35	8.96	9.67	6.12
14.64	0.53	-0.35	8.98	9.67	6.12
14.67	0.53	-0.36	8.99	9.68	6.11
14.69	0.53	-0.36	9.00	9.70	6.10
14.72	0.53	-0.36	9.01	9.69	6.11
14.75	0.53	-0.36	9.02	9.67	6.14
14.78	0.53	-0.36	9.03	9.68	6.13
14.81	0.53	-0.36	9.04	9.68	6.13
14.83	0.53	-0.36	9.05	9.70	6.12
14.86	0.54	-0.36	9.06	9.68	6.14
14.89	0.54	-0.36	9.07	9.68	6.15
14.92	0.54	-0.36	9.08	9.67	6.15
14.94	0.54	-0.36	9.09	9.67	6.16
14.97	0.54	-0.36	9.10	9.70	6.13
15.00	0.54	-0.36	9.11	9.68	6.15
15.03	0.54	-0.37	9.12	9.68	6.16
15.06	0.54	-0.37	9.13	9.67	6.17
15.08	0.54	-0.37	9.14	9.67	6.18
15.11	0.54	-0.37	9.15	9.69	6.16
15.14	0.55	-0.37	9.16	9.69	6.17
15.17	0.55	-0.37	9.17	9.69	6.17
15.19	0.55	-0.37	9.17	9.68	6.18
15.22	0.55	-0.37	9.19	9.68	6.18
15.25	0.55	-0.37	9.19	9.69	6.17
15.28	0.55	-0.37	9.21	9.68	6.19
15.31	0.55	-0.37	9.22	9.68	6.19
15.33	0.55	-0.37	9.22	9.68	6.19
15.36	0.55	-0.37	9.23	9.69	6.19
15.39	0.55	-0.38	9.24	9.69	6.19
15.42	0.56	-0.38	9.26	9.69	6.20
15.44	0.56	-0.38	9.26	9.67	6.21
15.47	0.56	-0.38	9.27	9.68	6.21
15.50	0.56	-0.38	9.28	9.69	6.20
15.53	0.56	-0.38	9.29	9.71	6.19
15.56	0.56	-0.38	9.30	9.69	6.21
15.58	0.56	-0.38	9.31	9.71	6.20
15.61	0.56	-0.38	9.32	9.70	6.21
15.64	0.56	-0.38	9.33	9.68	6.23
15.67	0.56	-0.38	9.34	9.68	6.23
15.69	0.57	-0.38	9.35	9.69	6.22
15.72	0.57	-0.38	9.36	9.70	6.22
15.75	0.57	-0.39	9.37	9.69	6.23
15.78	0.57	-0.39	9.38	9.72	6.21
15.81	0.57	-0.39	9.39	9.71	6.22
15.83	0.57	-0.39	9.40	9.70	6.23
15.86	0.57	-0.39	9.41	9.70	6.24
15.89	0.57	-0.39	9.42	9.72	6.22
15.92	0.57	-0.39	9.43	9.74	6.20
15.94	0.58	-0.39	9.44	9.69	6.25
15.97	0.58	-0.39	9.44	9.70	6.25
16.00	0.58	-0.39	9.46	9.70	6.25
16.03	0.58	-0.39	9.46	9.71	6.24
16.06	0.58	-0.39	9.47	9.70	6.26
16.08	0.58	-0.39	9.48	9.69	6.27
16.11	0.58	-0.40	9.49	9.69	6.27
16.14	0.58	-0.40	9.50	9.69	6.27
16.17	0.58	-0.40	9.51	9.70	6.27
16.19	0.58	-0.40	9.52	9.71	6.26
16.22	0.59	-0.40	9.53	9.71	6.27
16.25	0.59	-0.40	9.54	9.69	6.29
16.28	0.59	-0.40	9.55	9.70	6.28
16.31	0.59	-0.40	9.56	9.72	6.27
16.33	0.59	-0.40	9.57	9.70	6.28
16.36	0.59	-0.40	9.58	9.69	6.30
16.39	0.59	-0.40	9.59	9.71	6.29
16.42	0.59	-0.40	9.59	9.71	6.29
16.44	0.59	-0.40	9.60	9.70	6.30
16.47	0.59	-0.41	9.61	9.71	6.29
16.50	0.60	-0.41	9.62	9.72	6.29
16.53	0.60	-0.41	9.63	9.72	6.29
16.56	0.60	-0.41	9.64	9.73	6.28
16.58	0.60	-0.41	9.65	9.70	6.31
16.61	0.60	-0.41	9.66	9.74	6.28
16.64	0.60	-0.41	9.67	9.70	6.32
16.67	0.60	-0.41	9.68	9.71	6.32
16.69	0.60	-0.41	9.68	9.72	6.31
16.72	0.60	-0.41	9.69	9.73	6.31
16.75	0.60	-0.41	9.70	9.71	6.33
16.78	0.61	-0.41	9.71	9.71	6.32
16.81	0.61	-0.41	9.72	9.73	6.31
16.83	0.61	-0.42	9.73	9.72	6.33
16.86	0.61	-0.42	9.74	9.71	6.34
16.89	0.61	-0.42	9.75	9.71	6.34
16.92	0.61	-0.42	9.76	9.72	6.33
16.94	0.61	-0.42	9.76	9.73	6.32
16.97	0.61	-0.42	9.78	9.72	6.34
17.00	0.61	-0.42	9.78	9.72	6.34
17.03	0.61	-0.42	9.79	9.72	6.35
17.06	0.62	-0.42	9.80	9.73	6.34
17.08	0.62	-0.42	9.81	9.74	6.33
17.11	0.62	-0.42	9.82	9.72	6.35
17.14	0.62	-0.42	9.83	9.72	6.36
17.17	0.62	-0.42	9.84	9.72	6.36
17.19	0.62	-0.43	9.84	9.73	6.35
17.22	0.62	-0.43	9.86	9.73	6.35
17.25	0.62	-0.43	9.86	9.72	6.37
17.28	0.62	-0.43	9.87	9.73	6.36
17.31	0.62	-0.43	9.88	9.72	6.37
17.33	0.63	-0.43	9.89	9.73	6.37
17.36	0.63	-0.43	9.90	9.74	6.36
17.39	0.63	-0.43	9.91	9.72	6.38
17.42	0.63	-0.43	9.91	9.74	6.37
17.44	0.63	-0.43	9.92	9.74	6.37
17.47	0.63	-0.43	9.93	9.74	6.37
17.50	0.63	-0.43	9.94	9.73	6.39
17.53	0.63	-0.44	9.95	9.74	6.37
17.56	0.63	-0.44	9.96	9.75	6.37
17.58	0.63	-0.44	9.96	9.75	6.37
17.61	0.64	-0.44	9.97	9.75	6.38
17.64	0.64	-0.44	9.98	9.74	6.38
17.67	0.64	-0.44	10.00	9.74	6.39
17.69	0.64	-0.44	10.00	9.74	6.39
17.72	0.64	-0.44	10.01	9.75	6.39
17.75	0.64	-0.44	10.02	9.74	6.40
17.78	0.64	-0.44	10.03	9.75	6.40
17.81	0.64	-0.44	10.04	9.74	6.40
17.83	0.64	-0.44	10.05	9.75	6.39
17.86	0.64	-0.44	10.05	9.74	6.41
17.89	0.65	-0.45	10.06	9.74	6.41
17.92	0.65	-0.45	10.07	9.74	6.41
17.94	0.65	-0.45	10.08	9.75	6.41
17.97	0.65	-0.45	10.09	9.76	6.41
18.00	0.65	-0.45	10.10	9.75	6.41
18.03	0.65	-0.45	10.11	9.75	6.42
18.06	0.65	-0.45	10.11	9.75	6.42
18.08	0.65	-0.45	10.12	9.75	6.42
18.11	0.65	-0.45	10.13	9.77	6.41
18.14	0.65	-0.45	10.14	9.76	6.42
18.17	0.66	-0.45	10.15	9.76	6.42
18.19	0.66	-0.45	10.16	9.77	6.42
18.22	0.66	-0.46	10.16	9.76	6.43
18.25	0.66	-0.46	10.17	9.76	6.43
18.28	0.66	-0.46	10.18	9.77	6.43
18.31	0.66	-0.46	10.19	9.77	6.42
18.33	0.66	-0.46	10.20	9.76	6.44
18.36	0.66	-0.46	10.20	9.77	6.44
18.39	0.66	-0.46	10.21	9.78	6.43
18.42	0.66	-0.46	10.22	9.80	6.41
18.44	0.67	-0.46	10.23	9.77	6.44
18.47	0.67	-0.46	10.24	9.78	6.43
18.50	0.67	-0.46	10.24	9.77	6.44
18.53	0.67	-0.46	10.25	9.77	6.45
18.56	0.67	-0.46	10.26	9.77	6.45
18.58	0.67	-0.47	10.27	9.77	6.45
18.61	0.67	-0.47	10.28	9.77	6.46
18.64	0.67	-0.47	10.28	9.76	6.46
18.67	0.67	-0.47	10.30	9.77	6.46
18.69	0.67	-0.47	10.31	9.78	6.45
18.72	0.68	-0.47	10.31	9.78	6.46
18.75	0.68	-0.47	10.32	9.76	6.48
18.78	0.68	-0.47	10.33	9.79	6.45
18.81	0.68	-0.47	10.34	9.81	6.44
18.83	0.68	-0.47	10.34	9.79	6.45
18.86	0.68	-0.47	10.35	9.80	6.45
18.89	0.68	-0.47	10.36	9.77	6.48
18.92	0.68	-0.48	10.37	9.78	6.47
18.94	0.68	-0.48	10.37	9.78	6.48
18.97	0.68	-0.48	10.38	9.78	6.49
19.00	0.69	-0.48	10.39	9.78	6.48
19.03	0.69	-0.48	10.40	9.78	6.49
19.06	0.69	-0.48	10.41	9.78	6.49
19.08	0.69	-0.48	10.42	9.78	6.49
19.11	0.69	-0.48	10.42	9.77	6.50
19.14	0.69	-0.48	10.43	9.79	6.49
19.17	0.69	-0.48	10.44	9.80	6.48
19.19	0.69	-0.48	10.45	9.78	6.50
19.22	0.69	-0.48	10.45	9.80	6.49
19.25	0.70	-0.48	10.46	9.79	6.50
19.28	0.70	-0.49	10.47	9.79	6.50
19.31	0.70	-0.49	10.48	9.78	6.51
19.33	0.70	-0.49	10.49	9.79	6.50
19.36	0.70	-0.49	10.49	9.80	6.50
19.39	0.70	-0.49	10.50	9.79	6.51
19.42	0.70	-0.49	10.51	9.79	6.51
19.44	0.70	-0.49	10.52	9.79	6.51
19.47	0.70	-0.49	10.52	9.80	6.51
19.50	0.70	-0.49	10.53	9.79	6.52
19.53	0.71	-0.49	10.54	9.79	6.52
19.56	0.71	-0.49	10.55	9.80	6.52
19.58	0.71	-0.49	10.56	9.80	6.52
19.61	0.71	-0.50	10.56	9.80	6.52
19.64	0.71	-0.50	10.57	9.79	6.53
19.67	0.71	-0.50	10.58	9.81	6.52
19.69	0.71	-0.50	10.58	9.80	6.53
19.72	0.71	-0.50	10.59	9.80	6.53
19.75	0.71	-0.50	10.60	9.80	6.53
19.78	0.71	-0.50	10.61	9.79	6.55
19.81	0.72	-0.50	10.62	9.81	6.53
19.83	0.72	-0.50	10.62	9.80	6.54
19.86	0.72	-0.50	10.63	9.81	6.53
19.89	0.72	-0.50	10.64	9.80	6.54
19.92	0.72	-0.50	10.64	9.80	6.55
19.94	0.72	-0.51	10.65	9.83	6.52
19.97	0.72	-0.51	10.66	9.85	6.50
20.00	0.72	-0.51	10.67	9.84	6.52
20.03	0.72	-0.51	10.66	9.84	6.52
20.06	0.72	-0.51	10.68	9.83	6.53
20.08	0.73	-0.51	10.69	9.83	6.54
20.11	0.73	-0.51	10.70	9.81	6.56
20.14	0.73	-0.51	10.70	9.82	6.54
20.17	0.73	-0.51	10.71	9.82	6.56
20.19	0.73	-0.51	10.72	9.86	6.51
20.22	0.73	-0.51	10.72	9.81	6.56
20.25	0.73	-0.51	10.73	9.81	6.57
20.28	0.73	-0.52	10.74	9.82	6.56
20.31	0.73	-0.52	10.75	9.83	6.55
20.33	0.73	-0.52	10.75	9.83	6.56
20.36	0.74	-0.52	10.76	9.85	6.54
20.39	0.74	-0.52	10.77	9.82	6.56
20.42	0.74	-0.52	10.77	9.83	6.56
20.44	0.74	-0.52	10.78	9.82	6.57
20.47	0.74	-0.52	10.79	9.83	6.57
20.50	0.74	-0.52	10.79	9.83	6.57
20.53	0.74	-0.52	10.81	9.83	6.57
20.56	0.74	-0.52	10.81	9.83	6.58
20.58	0.74	-0.52	10.82	9.83	6.57
20.61	0.74	-0.53	10.82	9.85	6.56
20.64	0.75	-0.53	10.83	9.84	6.57
20.67	0.75	-0.53	10.84	9.85	6.57
20.69	0.75	-0.53	10.84	9.84	6.57
20.72	0.75	-0.53	10.85	9.84	6.58
20.75	0.75	-0.53	10.85	9.84	6.58
20.78	0.75	-0.53	10.86	9.84	6.58
20.81	0.75	-0.53	10.86	9.84	6.58
20.83	0.75	-0.53	10.87	9.84	6.58
20.86	0.75	-0.53	10.88	9.85	6.58
20.89	0.75	-0.53	10.88	9.85	6.58
20.92	0.76	-0.53	10.89	9.84	6.59
20.94	0.76	-0.54	10.90	9.84	6.59
20.97	0.76	-0.54	10.90	9.84	6.59
21.00	0.76	-0.54	10.91	9.86	6.58
21.03	0.76	-0.54	10.91	9.86	6.58
21.06	0.76	-0.54	10.92	9.88	6.56
21.08	0.76	-0.54	10.93	9.84	6.60
21.11	0.76	-0.54	10.93	9.84	6.60
21.14	0.76	-0.54	10.94	9.88	6.57
21.17	0.76	-0.54	10.94	9.86	6.59
21.19	0.77	-0.54	10.95	9.86	6.59
21.22	0.77	-0.54	10.95	9.86	6.59
21.25	0.77	-0.54	10.96	9.85	6.61
21.28	0.77	-0.54	10.96	9.84	6.61
21.31	0.77	-0.55	10.97	9.86	6.60
21.33	0.77	-0.55	10.98	9.86	6.60
21.36	0.77	-0.55	10.97	9.86	6.60
21.39	0.77	-0.55	10.99	9.85	6.61
21.42	0.77	-0.55	10.99	9.86	6.61
21.44	0.77	-0.55	10.99	9.86	6.60
21.47	0.78	-0.55	11.00	9.88	6.58
21.50	0.78	-0.55	11.00	9.86	6.61
21.53	0.78	-0.55	11.01	9.85	6.62
21.56	0.78	-0.55	11.01	9.87	6.60
21.58	0.78	-0.55	11.02	9.87	6.61
21.61	0.78	-0.55	11.02	9.88	6.59
21.64	0.78	-0.55	11.02	9.86	6.62
21.67	0.78	-0.56	11.03	9.87	6.61
21.69	0.78	-0.56	11.03	9.86	6.62
21.72	0.78	-0.56	11.04	9.87	6.61
21.75	0.79	-0.56	11.04	9.86	6.62
21.78	0.79	-0.56	11.05	9.88	6.60
21.81	0.79	-0.56	11.05	9.88	6.60
21.83	0.79	-0.56	11.05	9.86	6.62
21.86	0.79	-0.56	11.05	9.88	6.61
21.89	0.79	-0.56	11.06	9.88	6.61
21.92	0.79	-0.56	11.06	9.87	6.61
21.94	0.79	-0.56	11.07	9.88	6.60
21.97	0.79	-0.56	11.07	9.86	6.63
22.00	0.79	-0.57	11.07	9.87	6.62
22.03	0.80	-0.57	11.08	9.89	6.61
22.06	0.80	-0.57	11.07	9.86	6.63
22.08	0.80	-0.57	11.08	9.87	6.62
22.11	0.80	-0.57	11.08	9.87	6.62
22.14	0.80	-0.57	11.09	9.87	6.62
22.17	0.80	-0.57	11.08	9.90	6.59
22.19	0.80	-0.57	11.08	9.86	6.64
22.22	0.80	-0.57	11.08	9.87	6.62
22.25	0.80	-0.57	11.09	9.88	6.61
22.28	0.80	-0.57	11.09	9.90	6.60
22.31	0.81	-0.57	11.09	9.90	6.60
22.33	0.81	-0.57	11.09	9.87	6.62
22.36	0.81	-0.57	11.09	9.88	6.62
22.39	0.81	-0.58	11.09	9.87	6.63
22.42	0.81	-0.58	11.09	9.87	6.62
22.44	0.81	-0.58	11.09	9.87	6.62
22.47	0.81	-0.58	11.09	9.87	6.63
22.50	0.81	-0.58	11.08	9.87	6.62
22.53	0.81	-0.58	11.08	9.87	6.62
22.56	0.82	-0.58	11.07	9.87	6.62
22.58	0.82	-0.58	11.07	9.86	6.63
22.61	0.82	-0.58	11.06	9.87	6.62
22.64	0.82	-0.58	11.04	9.86	6.62
22.67	0.82	-0.58	11.02	9.86	6.62
22.69	0.82	-0.58	11.01	9.86	6.61
22.72	0.82	-0.58	10.99	9.86	6.60
22.75	0.82	-0.58	10.97	9.86	6.60
22.78	0.82	-0.59	10.95	9.86	6.60
22.81	0.82	-0.59	10.94	9.85	6.59
22.83	0.83	-0.59	10.92	9.85	6.59
22.86	0.83	-0.59	10.91	9.85	6.59
22.89	0.83	-0.59	10.89	9.85	6.58
22.92	0.83	-0.59	10.88	9.85	6.58
22.94	0.83	-0.59	10.86	9.85	6.57
22.97	0.83	-0.59	10.85	9.85	6.57
23.00	0.83	-0.59	10.83	9.84	6.57
23.03	0.83	-0.59	10.82	9.85	6.56
23.06	0.83	-0.59	10.80	9.85	6.55
23.08	0.83	-0.60	10.78	9.84	6.55
23.11	0.84	-0.60	10.76	9.85	6.53
23.14	0.84	-0.60	10.74	9.84	6.54
23.17	0.84	-0.60	10.72	9.85	6.52
23.19	0.84	-0.60	10.71	9.85	6.52
23.22	0.84	-0.60	10.70	9.84	6.52
23.25	0.84	-0.60	10.68	9.84	6.52
23.28	0.84	-0.60	10.67	9.85	6.51
23.31	0.84	-0.60	10.65	9.84	6.51
23.33	0.84	-0.61	10.64	9.83	6.51
23.36	0.84	-0.61	10.61	9.84	6.50
23.39	0.85	-0.61	10.59	9.84	6.49
23.42	0.85	-0.61	10.56	9.84	6.48
23.44	0.85	-0.61	10.52	9.83	6.48
23.47	0.85	-0.61	10.48	9.83	6.47
23.50	0.85	-0.62	10.45	9.81	6.47
23.53	0.85	-0.62	10.40	9.82	6.45
23.56	0.85	-0.62	10.35	9.82	6.43
23.58	0.85	-0.62	10.30	9.81	6.42
23.61	0.85	-0.63	10.23	9.79	6.42
23.64	0.85	-0.63	10.17	9.78	6.41
23.67	0.86	-0.63	10.11	9.79	6.39
23.69	0.86	-0.63	10.06	9.79	6.37
23.72	0.86	-0.64	10.02	9.77	6.37
23.75	0.86	-0.64	9.99	9.78	6.35
23.78	0.86	-0.64	9.96	9.78	6.34
23.81	0.86	-0.64	9.92	9.78	6.33
23.83	0.86	-0.65	9.88	9.77	6.32
23.86	0.86	-0.65	9.85	9.78	6.31
23.89	0.86	-0.65	9.81	9.77	6.30
23.92	0.86	-0.65	9.77	9.77	6.29
23.94	0.87	-0.66	9.72	9.77	6.27
23.97	0.87	-0.66	9.68	9.75	6.27
24.00	0.87	-0.66	9.63	9.77	6.24
24.03	0.87	-0.66	9.57	9.76	6.23
24.06	0.87	-0.67	9.51	9.75	6.22
24.08	0.87	-0.67	9.45	9.74	6.21
24.11	0.87	-0.67	9.38	9.74	6.19
24.14	0.87	-0.68	9.29	9.70	6.19
24.17	0.87	-0.68	9.15	9.71	6.14
24.19	0.87	-0.68	8.97	9.68	6.11
24.22	0.88	-0.69	8.71	9.62	6.08
24.25	0.88	-0.69	8.49	9.59	6.04
24.28	0.88	-0.69	8.36	9.59	6.00
24.31	0.88	-0.70	8.26	9.59	5.96
24.33	0.88	-0.70	8.20	9.59	5.94
24.36	0.88	-0.70	8.14	9.59	5.92
24.39	0.88	-0.70	8.09	9.59	5.91
24.42	0.88	-0.70	8.06	9.60	5.89
24.44	0.88	-0.71	8.02	9.60	5.87
24.47	0.88	-0.71	7.99	9.61	5.86
24.50	0.89	-0.71	7.97	9.62	5.83
24.53	0.89	-0.71	7.94	9.65	5.80
24.56	0.89	-0.71	7.92	9.65	5.79
24.58	0.89	-0.72	7.90	9.64	5.80
24.61	0.89	-0.72	7.88	9.64	5.79
24.64	0.89	-0.72	7.86	9.63	5.79
24.67	0.89	-0.72	7.85	9.64	5.78
24.69	0.89	-0.72	7.83	9.65	5.77
24.72	0.89	-0.72	7.82	9.65	5.76
24.75	0.89	-0.73	7.80	9.65	5.76
24.78	0.90	-0.73	7.79	9.64	5.76
24.81	0.90	-0.73	7.78	9.64	5.75
24.83	0.90	-0.73	7.77	9.67	5.72
24.86	0.90	-0.73	7.76	9.66	5.73
24.89	0.90	-0.73	7.75	9.66	5.72
24.92	0.90	-0.73	7.74	9.67	5.71
24.94	0.90	-0.74	7.73	9.67	5.71
24.97	0.90	-0.74	7.72	9.67	5.70
25.00	0.90	-0.74	7.71	9.67	5.70
25.03	0.90	-0.74	7.70	9.67	5.69
25.06	0.91	-0.74	7.69	9.66	5.70
25.08	0.91	-0.74	7.68	9.67	5.68
25.11	0.91	-0.75	7.67	9.68	5.67
25.14	0.91	-0.75	7.66	9.67	5.69
25.17	0.91	-0.75	7.65	9.69	5.67
25.19	0.91	-0.75	7.65	9.68	5.66
25.22	0.91	-0.75	7.63	9.68	5.67
25.25	0.91	-0.75	7.62	9.69	5.65
25.28	0.91	-0.75	7.62	9.69	5.65
25.31	0.91	-0.76	7.62	9.69	5.64
25.33	0.92	-0.76	7.61	9.68	5.65
25.36	0.92	-0.76	7.60	9.70	5.64
25.39	0.92	-0.76	7.59	9.68	5.65
25.42	0.92	-0.76	7.59	9.70	5.63
25.44	0.92	-0.76	7.58	9.70	5.63
25.47	0.92	-0.76	7.57	9.69	5.64
25.50	0.92	-0.77	7.57	9.70	5.62
25.53	0.92	-0.77	7.56	9.71	5.61
25.56	0.92	-0.77	7.55	9.69	5.63
25.58	0.92	-0.77	7.55	9.70	5.62
25.61	0.93	-0.77	7.54	9.70	5.61
25.64	0.93	-0.77	7.54	9.70	5.61
25.67	0.93	-0.77	7.53	9.69	5.62
25.69	0.93	-0.78	7.53	9.72	5.59
25.72	0.93	-0.78	7.52	9.70	5.61
25.75	0.93	-0.78	7.51	9.74	5.57
25.78	0.93	-0.78	7.50	9.75	5.56
25.81	0.93	-0.78	7.50	9.70	5.60
25.83	0.93	-0.78	7.49	9.71	5.59
25.86	0.94	-0.78	7.48	9.71	5.58
25.89	0.94	-0.79	7.48	9.70	5.59
25.92	0.94	-0.79	7.47	9.72	5.57
25.94	0.94	-0.79	7.47	9.73	5.56
25.97	0.94	-0.79	7.46	9.71	5.58
26.00	0.94	-0.79	7.46	9.74	5.55
26.03	0.94	-0.79	7.45	9.72	5.57
26.06	0.94	-0.79	7.45	9.71	5.57
26.08	0.94	-0.79	7.44	9.72	5.56
26.11	0.94	-0.80	7.44	9.71	5.57
26.14	0.95	-0.80	7.43	9.72	5.56
26.17	0.95	-0.80	7.43	9.72	5.56
26.19	0.95	-0.80	7.43	9.71	5.56
26.22	0.95	-0.80	7.42	9.72	5.56
26.25	0.95	-0.80	7.42	9.71	5.56
26.28	0.95	-0.80	7.41	9.71	5.56
26.31	0.95	-0.81	7.41	9.72	5.55
26.33	0.95	-0.81	7.41	9.71	5.56
26.36	0.95	-0.81	7.40	9.72	5.55
26.39	0.95	-0.81	7.40	9.71	5.55
26.42	0.96	-0.81	7.39	9.72	5.55
26.44	0.96	-0.81	7.39	9.72	5.54
26.47	0.96	-0.81	7.39	9.72	5.55
26.50	0.96	-0.82	7.38	9.72	5.54
26.53	0.96	-0.82	7.38	9.72	5.54
26.56	0.96	-0.82	7.37	9.72	5.54
26.58	0.96	-0.82	7.37	9.73	5.53
26.61	0.96	-0.82	7.37	9.72	5.53
26.64	0.96	-0.82	7.36	9.72	5.53
26.67	0.96	-0.82	7.36	9.73	5.52
26.69	0.97	-0.82	7.36	9.73	5.52
26.72	0.97	-0.83	7.35	9.73	5.52
26.75	0.97	-0.83	7.35	9.74	5.51
26.78	0.97	-0.83	7.35	9.73	5.52
26.81	0.97	-0.83	7.34	9.73	5.52
26.83	0.97	-0.83	7.36	9.74	5.51
26.86	0.97	-0.83	7.33	9.74	5.51
26.89	0.97	-0.83	7.33	9.73	5.51
26.92	0.97	-0.84	7.33	9.73	5.52
26.94	0.97	-0.84	7.33	9.73	5.51
26.97	0.98	-0.84	7.32	9.74	5.50
27.00	0.98	-0.84	7.32	9.73	5.51
27.03	0.98	-0.84	7.31	9.74	5.50
27.06	0.98	-0.84	7.31	9.73	5.51
27.08	0.98	-0.84	7.31	9.73	5.51
27.11	0.98	-0.84	7.31	9.73	5.51
27.14	0.98	-0.85	7.31	9.74	5.50
27.17	0.98	-0.85	7.30	9.75	5.49
27.19	0.98	-0.85	7.30	9.74	5.49
27.22	0.98	-0.85	7.30	9.74	5.50
27.25	0.99	-0.85	7.29	9.74	5.49
27.28	0.99	-0.85	7.29	9.75	5.48
27.31	0.99	-0.85	7.29	9.75	5.48
27.33	0.99	-0.86	7.29	9.74	5.49
27.36	0.99	-0.86	7.29	9.74	5.48
27.39	0.99	-0.86	7.28	9.75	5.48
27.42	0.99	-0.86	7.28	9.74	5.48
27.44	0.99	-0.86	7.28	9.75	5.47
27.47	0.99	-0.86	7.28	9.75	5.48
27.50	0.99	-0.86	7.27	9.75	5.47
27.53	1.00	-0.86	7.27	9.75	5.47
27.56	1.00	-0.87	7.27	9.75	5.47
27.58	1.00	-0.87	7.27	9.75	5.47
27.61	1.00	-0.87	7.27	9.74	5.49
27.64	1.00	-0.87	7.26	9.75	5.47
27.67	1.00	-0.87	7.26	9.76	5.46
27.69	1.00	-0.87	7.26	9.76	5.46
27.72	1.00	-0.87	7.25	9.74	5.48
27.75	1.00	-0.88	7.25	9.76	5.46
27.78	1.00	-0.88	7.25	9.76	5.46
27.81	1.01	-0.88	7.25	9.75	5.47
27.83	1.01	-0.88	7.24	9.76	5.46
27.86	1.01	-0.88	7.24	9.76	5.46
27.89	1.01	-0.88	7.24	9.76	5.46
27.92	1.01	-0.88	7.24	9.75	5.46
27.94	1.01	-0.88	7.24	9.75	5.46
27.97	1.01	-0.89	7.24	9.77	5.45
28.00	1.01	-0.89	7.23	9.77	5.44
28.03	1.01	-0.89	7.23	9.77	5.44
28.06	1.01	-0.89	7.23	9.77	5.44
28.08	1.02	-0.89	7.23	9.78	5.43
28.11	1.02	-0.89	7.23	9.76	5.44
28.14	1.02	-0.89	7.23	9.76	5.45
28.17	1.02	-0.89	7.22	9.77	5.44
28.19	1.02	-0.90	7.22	9.76	5.45
28.22	1.02	-0.90	7.22	9.76	5.44
28.25	1.02	-0.90	7.22	9.77	5.44
28.28	1.02	-0.90	7.22	9.76	5.44
28.31	1.02	-0.90	7.21	9.76	5.44
28.33	1.02	-0.90	7.21	9.76	5.44
28.36	1.03	-0.90	7.21	9.77	5.44
28.39	1.03	-0.91	7.21	9.76	5.44
28.42	1.03	-0.91	7.21	9.77	5.43
28.44	1.03	-0.91	7.20	9.77	5.43
28.47	1.03	-0.91	7.20	9.77	5.43
28.50	1.03	-0.91	7.20	9.77	5.43
28.53	1.03	-0.91	7.20	9.77	5.43
28.56	1.03	-0.91	7.20	9.76	5.44
28.58	1.03	-0.91	7.19	9.78	5.42
28.61	1.03	-0.92	7.19	9.77	5.42
28.64	1.04	-0.92	7.19	9.79	5.41
28.67	1.04	-0.92	7.19	9.81	5.39
28.69	1.04	-0.92	7.18	9.81	5.39
28.72	1.04	-0.92	7.18	9.77	5.42
28.75	1.04	-0.92	7.18	9.78	5.42
28.78	1.04	-0.92	7.18	9.77	5.42
28.81	1.04	-0.92	7.18	9.77	5.42
28.83	1.04	-0.93	7.18	9.77	5.42
28.86	1.04	-0.93	7.18	9.78	5.42
28.89	1.04	-0.93	7.17	9.77	5.42
28.92	1.05	-0.93	7.17	9.77	5.42
28.94	1.05	-0.93	7.17	9.77	5.42
28.97	1.05	-0.93	7.17	9.78	5.41
29.00	1.05	-0.93	7.17	9.78	5.41
29.03	1.05	-0.93	7.17	9.77	5.42
29.06	1.05	-0.94	7.17	9.78	5.41
29.08	1.05	-0.94	7.16	9.77	5.42
29.11	1.05	-0.94	7.16	9.78	5.41
29.14	1.05	-0.94	7.16	9.78	5.41
29.17	1.06	-0.94	7.16	9.77	5.41
29.19	1.06	-0.94	7.16	9.77	5.41
29.22	1.06	-0.94	7.16	9.77	5.41
29.25	1.06	-0.95	7.15	9.78	5.40
29.28	1.06	-0.95	7.15	9.78	5.41
29.31	1.06	-0.95	7.15	9.77	5.41
29.33	1.06	-0.95	7.15	9.78	5.40
29.36	1.06	-0.95	7.15	9.78	5.41
29.39	1.06	-0.95	7.15	9.78	5.41
29.42	1.06	-0.95	7.15	9.78	5.40
29.44	1.07	-0.95	7.14	9.79	5.40
29.47	1.07	-0.96	7.14	9.77	5.41
29.50	1.07	-0.96	7.14	9.78	5.40
29.53	1.07	-0.96	7.14	9.78	5.40
29.56	1.07	-0.96	7.14	9.78	5.40
29.58	1.07	-0.96	7.14	9.78	5.39
29.61	1.07	-0.96	7.13	9.77	5.40
29.64	1.07	-0.96	7.13	9.79	5.38
29.67	1.07	-0.96	7.13	9.79	5.39
29.69	1.07	-0.97	7.13	9.78	5.40
29.72	1.08	-0.97	7.13	9.78	5.40
29.75	1.08	-0.97	7.13	9.79	5.39
29.78	1.08	-0.97	7.12	9.79	5.39
29.81	1.08	-0.97	7.12	9.78	5.39
29.83	1.08	-0.97	7.12	9.79	5.38
29.86	1.08	-0.97	7.12	9.80	5.38
29.89	1.08	-0.97	7.12	9.79	5.39
29.92	1.08	-0.98	7.12	9.79	5.38
29.94	1.08	-0.98	7.12	9.78	5.39
29.97	1.08	-0.98	7.04	9.77	5.37
30.00	1.09	-0.98	7.06	9.78	5.38
30.03	1.09	-0.98	7.07	9.78	5.37
30.06	1.09	-0.98	7.08	9.79	5.38
30.08	1.09	-0.98	7.09	9.78	5.38
30.11	1.09	-0.98	7.09	9.79	5.37
30.14	1.09	-0.99	7.09	9.79	5.37
30.17	1.09	-0.99	7.09	9.79	5.38
30.19	1.09	-0.99	7.09	9.79	5.37
30.22	1.09	-0.99	7.09	9.79	5.38
30.25	1.09	-0.99	7.09	9.80	5.36
30.28	1.10	-0.99	7.09	9.80	5.37
30.31	1.10	-0.99	7.09	9.80	5.37
30.33	1.10	-1.00	7.09	9.80	5.37
30.36	1.10	-1.00	7.09	9.79	5.38
30.39	1.10	-1.00	7.09	9.80	5.36
30.42	1.10	-1.00	7.09	9.79	5.37
30.44	1.10	-1.00	7.09	9.80	5.36
30.47	1.10	-1.00	7.09	9.79	5.37
30.50	1.10	-1.00	7.09	9.80	5.36
30.53	1.10	-1.00	7.09	9.80	5.36
30.56	1.11	-1.01	7.09	9.80	5.36
30.58	1.11	-1.01	7.08	9.79	5.37
30.61	1.11	-1.01	7.09	9.81	5.35
30.64	1.11	-1.01	7.09	9.80	5.36
30.67	1.11	-1.01	7.08	9.81	5.35
30.69	1.11	-1.01	7.08	9.81	5.35
30.72	1.11	-1.01	7.08	9.81	5.35
30.75	1.11	-1.01	7.08	9.81	5.34
30.78	1.11	-1.02	7.08	9.82	5.34
30.81	1.11	-1.02	7.08	9.81	5.35
30.83	1.12	-1.02	7.08	9.81	5.35
30.86	1.12	-1.02	7.08	9.81	5.35
30.89	1.12	-1.02	7.08	9.80	5.35
30.92	1.12	-1.02	7.07	9.80	5.35
30.94	1.12	-1.02	7.07	9.81	5.35
30.97	1.12	-1.02	7.07	9.81	5.35
31.00	1.12	-1.03	7.07	9.80	5.36
31.03	1.12	-1.03	7.07	9.81	5.34
31.06	1.12	-1.03	7.07	9.80	5.35
31.08	1.12	-1.03	7.07	9.80	5.36
31.11	1.13	-1.03	7.06	9.81	5.35
31.14	1.13	-1.03	7.06	9.82	5.33
31.17	1.13	-1.03	7.06	9.81	5.35
31.19	1.13	-1.03	7.06	9.81	5.35
31.22	1.13	-1.04	7.06	9.81	5.34
31.25	1.13	-1.04	7.06	9.81	5.34
31.28	1.13	-1.04	7.05	9.80	5.35
31.31	1.13	-1.04	7.05	9.81	5.34
31.33	1.13	-1.04	7.05	9.81	5.34
31.36	1.13	-1.04	7.05	9.80	5.35
31.39	1.14	-1.04	7.05	9.81	5.34
31.42	1.14	-1.04	7.05	9.81	5.34
31.44	1.14	-1.05	7.05	9.80	5.34
31.47	1.14	-1.05	7.04	9.80	5.34
31.50	1.14	-1.05	7.04	9.80	5.34
31.53	1.14	-1.05	7.04	9.80	5.34
31.56	1.14	-1.05	7.04	9.81	5.34
31.58	1.14	-1.05	7.04	9.80	5.34
31.61	1.14	-1.05	7.04	9.80	5.35
31.64	1.14	-1.05	7.04	9.82	5.33
31.67	1.15	-1.06	6.94	9.78	5.34
31.69	1.15	-1.06	6.96	9.80	5.32
31.72	1.15	-1.06	6.98	9.80	5.33
31.75	1.15	-1.06	7.00	9.80	5.34
31.78	1.15	-1.06	7.01	9.81	5.32
31.81	1.15	-1.06	7.01	9.82	5.32
31.83	1.15	-1.06	7.02	9.81	5.33
31.86	1.15	-1.06	7.02	9.81	5.33
31.89	1.15	-1.07	7.02	9.80	5.34
31.92	1.15	-1.07	7.02	9.82	5.33
31.94	1.16	-1.07	7.02	9.81	5.33
31.97	1.16	-1.07	7.02	9.81	5.33
32.00	1.16	-1.07	7.02	9.81	5.33
32.03	1.16	-1.07	7.02	9.81	5.33
32.06	1.16	-1.07	7.02	9.81	5.33
32.08	1.16	-1.07	7.02	9.81	5.33
32.11	1.16	-1.08	7.02	9.82	5.32
32.14	1.16	-1.08	7.02	9.82	5.32
32.17	1.16	-1.08	7.02	9.81	5.33
32.19	1.16	-1.08	7.02	9.81	5.33
32.22	1.17	-1.08	7.02	9.81	5.33
32.25	1.17	-1.08	7.01	9.82	5.31
32.28	1.17	-1.08	7.01	9.81	5.32
32.31	1.17	-1.08	7.01	9.81	5.33
32.33	1.17	-1.09	7.01	9.82	5.32
32.36	1.17	-1.09	7.01	9.81	5.32
32.39	1.17	-1.09	7.01	9.81	5.32
32.42	1.17	-1.09	7.01	9.81	5.33
32.44	1.17	-1.09	7.01	9.82	5.32
32.47	1.18	-1.09	7.01	9.82	5.31
32.50	1.18	-1.09	7.01	9.82	5.31
32.53	1.18	-1.10	7.01	9.83	5.31
32.56	1.18	-1.10	7.01	9.82	5.32
32.58	1.18	-1.10	7.00	9.82	5.32
32.61	1.18	-1.10	7.00	9.82	5.32
32.64	1.18	-1.10	7.00	9.82	5.31
32.67	1.18	-1.10	7.00	9.82	5.32
32.69	1.18	-1.10	7.00	9.82	5.31
32.72	1.18	-1.10	7.00	9.82	5.31
32.75	1.19	-1.11	7.00	9.82	5.31
32.78	1.19	-1.11	7.00	9.81	5.32
32.81	1.19	-1.11	7.00	9.82	5.32
32.83	1.19	-1.11	7.00	9.83	5.30
32.86	1.19	-1.11	7.00	9.83	5.30
32.89	1.19	-1.11	6.99	9.84	5.29
32.92	1.19	-1.11	6.99	9.83	5.30
32.94	1.19	-1.11	7.00	9.83	5.30
32.97	1.19	-1.12	6.99	9.82	5.31
33.00	1.19	-1.12	6.99	9.82	5.31
33.03	1.20	-1.12	6.99	9.83	5.30
33.06	1.20	-1.12	6.99	9.83	5.31
33.08	1.20	-1.12	6.99	9.81	5.32
33.11	1.20	-1.12	6.99	9.83	5.30
33.14	1.20	-1.12	6.99	9.83	5.30
33.17	1.20	-1.12	6.99	9.81	5.32
33.19	1.20	-1.13	6.99	9.84	5.29
33.22	1.20	-1.13	6.99	9.83	5.30
33.25	1.20	-1.13	6.93	9.81	5.30
33.28	1.20	-1.13	6.94	9.81	5.30
33.31	1.21	-1.13	6.96	9.82	5.30
33.33	1.21	-1.13	6.97	9.82	5.31
33.36	1.21	-1.13	6.97	9.83	5.30
33.39	1.21	-1.13	6.97	9.82	5.30
33.42	1.21	-1.14	6.98	9.83	5.29
33.44	1.21	-1.14	6.98	9.83	5.30
33.47	1.21	-1.14	6.98	9.83	5.29
33.50	1.21	-1.14	6.98	9.83	5.29
33.53	1.21	-1.14	6.98	9.83	5.30
33.56	1.21	-1.14	6.98	9.82	5.30
33.58	1.22	-1.14	6.97	9.84	5.28
33.61	1.22	-1.14	6.98	9.83	5.29
33.64	1.22	-1.15	6.97	9.84	5.29
33.67	1.22	-1.15	6.97	9.83	5.29
33.69	1.22	-1.15	6.97	9.83	5.30
33.72	1.22	-1.15	6.97	9.82	5.30
33.75	1.22	-1.15	6.97	9.82	5.30
33.78	1.22	-1.15	6.97	9.83	5.29
33.81	1.22	-1.15	6.97	9.83	5.29
33.83	1.22	-1.15	6.97	9.82	5.30
33.86	1.23	-1.16	6.97	9.84	5.28
33.89	1.23	-1.16	6.97	9.83	5.29
33.92	1.23	-1.16	6.97	9.83	5.30
33.94	1.23	-1.16	6.97	9.83	5.30
33.97	1.23	-1.16	6.97	9.83	5.29
34.00	1.23	-1.16	6.97	9.83	5.29
34.03	1.23	-1.16	6.97	9.83	5.29
34.06	1.23	-1.16	6.96	9.82	5.30
34.08	1.23	-1.17	6.97	9.82	5.30
34.11	1.23	-1.17	6.96	9.83	5.29
34.14	1.24	-1.17	6.96	9.82	5.30
34.17	1.24	-1.17	6.96	9.83	5.29
34.19	1.24	-1.17	6.96	9.84	5.28
34.22	1.24	-1.17	6.96	9.83	5.29
34.25	1.24	-1.17	6.96	9.82	5.30
34.28	1.24	-1.17	6.96	9.83	5.29
34.31	1.24	-1.18	6.96	9.83	5.29
34.33	1.24	-1.18	6.96	9.83	5.29
34.36	1.24	-1.18	6.96	9.82	5.30
34.39	1.24	-1.18	6.95	9.84	5.28
34.42	1.25	-1.18	6.95	9.84	5.28
34.44	1.25	-1.18	6.95	9.84	5.28
34.47	1.25	-1.18	6.96	9.83	5.29
34.50	1.25	-1.18	6.95	9.83	5.29
34.53	1.25	-1.19	6.95	9.84	5.28
34.56	1.25	-1.19	6.95	9.84	5.28
34.58	1.25	-1.19	6.95	9.84	5.28
34.61	1.25	-1.19	6.95	9.83	5.29
34.64	1.25	-1.19	6.95	9.84	5.28
34.67	1.25	-1.19	6.95	9.84	5.28
34.69	1.26	-1.19	6.95	9.83	5.29
34.72	1.26	-1.19	6.95	9.82	5.29
34.75	1.26	-1.20	6.94	9.83	5.28
34.78	1.26	-1.20	6.95	9.85	5.26
34.81	1.26	-1.20	6.94	9.84	5.27
34.83	1.26	-1.20	6.94	9.83	5.28
34.86	1.26	-1.20	6.94	9.85	5.26
34.89	1.26	-1.20	6.94	9.84	5.27
34.92	1.26	-1.20	6.94	9.83	5.28
34.94	1.26	-1.20	6.94	9.86	5.26
34.97	1.27	-1.21	6.94	9.85	5.27
35.00	1.27	-1.21	6.94	9.84	5.27
35.03	1.27	-1.21	6.94	9.84	5.27
35.06	1.27	-1.21	6.94	9.84	5.27
35.08	1.27	-1.21	6.94	9.84	5.27
35.11	1.27	-1.21	6.94	9.85	5.27
35.14	1.27	-1.21	6.94	9.84	5.27
35.17	1.27	-1.21	6.94	9.84	5.27
35.19	1.27	-1.22	6.94	9.84	5.27
35.22	1.27	-1.22	6.94	9.84	5.28
35.25	1.28	-1.22	6.94	9.84	5.28
35.28	1.28	-1.22	6.93	9.84	5.27
35.31	1.28	-1.22	6.94	9.84	5.27
35.33	1.28	-1.22	6.94	9.84	5.27
35.36	1.28	-1.22	6.93	9.84	5.27
35.39	1.28	-1.23	6.93	9.85	5.26
35.42	1.28	-1.23	6.93	9.85	5.26
35.44	1.28	-1.23	6.93	9.86	5.26
35.47	1.28	-1.23	6.93	9.85	5.26
35.50	1.28	-1.23	6.93	9.86	5.25
35.53	1.29	-1.23	6.93	9.86	5.25
35.56	1.29	-1.23	6.93	9.85	5.26
35.58	1.29	-1.23	6.93	9.85	5.26
35.61	1.29	-1.23	6.93	9.85	5.26
35.64	1.29	-1.24	6.93	9.85	5.26
35.67	1.29	-1.24	6.93	9.85	5.26
35.69	1.29	-1.24	6.93	9.85	5.26
35.72	1.29	-1.24	6.93	9.84	5.27
35.75	1.29	-1.24	6.93	9.86	5.25
35.78	1.30	-1.24	6.93	9.85	5.26
35.81	1.30	-1.24	6.92	9.85	5.26
35.83	1.30	-1.24	6.92	9.84	5.26
35.86	1.30	-1.25	6.92	9.84	5.26
35.89	1.30	-1.25	6.92	9.85	5.26
35.92	1.30	-1.25	6.92	9.84	5.27
35.94	1.30	-1.25	6.92	9.85	5.26
35.97	1.30	-1.25	6.92	9.85	5.26
36.00	1.30	-1.25	6.92	9.84	5.26
36.03	1.30	-1.25	6.92	9.86	5.25
36.06	1.31	-1.25	6.91	9.84	5.26
36.08	1.31	-1.26	6.92	9.85	5.26
36.11	1.31	-1.26	6.92	9.84	5.26
36.14	1.31	-1.26	6.92	9.84	5.26
36.17	1.31	-1.26	6.92	9.85	5.26
36.19	1.31	-1.26	6.92	9.84	5.26
36.22	1.31	-1.26	6.92	9.84	5.26
36.25	1.31	-1.26	6.92	9.85	5.26
36.28	1.31	-1.26	6.92	9.85	5.26
36.31	1.31	-1.27	6.92	9.85	5.25
36.33	1.32	-1.27	6.92	9.84	5.26
36.36	1.32	-1.27	6.92	9.85	5.25
36.39	1.32	-1.27	6.92	9.84	5.26
36.42	1.32	-1.27	6.92	9.85	5.26
36.44	1.32	-1.27	6.91	9.85	5.25
36.47	1.32	-1.27	6.92	9.84	5.26
36.50	1.32	-1.28	6.92	9.85	5.26
36.53	1.32	-1.28	6.91	9.85	5.25
36.56	1.32	-1.28	6.91	9.86	5.25
36.58	1.32	-1.28	6.91	9.84	5.26
36.61	1.33	-1.28	6.91	9.85	5.25
36.64	1.33	-1.28	6.91	9.86	5.25
36.67	1.33	-1.28	6.91	9.85	5.25
36.69	1.33	-1.28	6.91	9.85	5.25
36.72	1.33	-1.28	6.91	9.85	5.25
36.75	1.33	-1.29	6.91	9.85	5.26
36.78	1.33	-1.29	6.91	9.85	5.25
36.81	1.33	-1.29	6.90	9.85	5.25
36.83	1.33	-1.29	6.91	9.85	5.25
36.86	1.33	-1.29	6.91	9.85	5.26
36.89	1.34	-1.29	6.91	9.85	5.25
36.92	1.34	-1.29	6.91	9.86	5.25
36.94	1.34	-1.30	6.91	9.86	5.24
36.97	1.34	-1.30	6.90	9.86	5.24
37.00	1.34	-1.30	6.91	9.85	5.25
37.03	1.34	-1.30	6.90	9.86	5.24
37.06	1.34	-1.30	6.90	9.85	5.25
37.08	1.34	-1.30	6.91	9.84	5.26
37.11	1.34	-1.30	6.90	9.86	5.24
37.14	1.34	-1.30	6.90	9.86	5.24
37.17	1.35	-1.31	6.90	9.86	5.24
37.19	1.35	-1.31	6.90	9.85	5.25
37.22	1.35	-1.31	6.91	9.86	5.25
37.25	1.35	-1.31	6.90	9.85	5.25
37.28	1.35	-1.31	6.90	9.86	5.24
37.31	1.35	-1.31	6.90	9.86	5.24
37.33	1.35	-1.31	6.90	9.85	5.25
37.36	1.35	-1.31	6.90	9.87	5.23
37.39	1.35	-1.31	6.90	9.86	5.24
37.42	1.35	-1.32	6.90	9.86	5.24
37.44	1.36	-1.32	6.90	9.86	5.24
37.47	1.36	-1.32	6.90	9.86	5.24
37.50	1.36	-1.32	6.90	9.85	5.25
37.53	1.36	-1.32	6.90	9.87	5.23
37.56	1.36	-1.32	6.90	9.87	5.23
37.58	1.36	-1.32	6.90	9.86	5.24
37.61	1.36	-1.33	6.90	9.86	5.24
37.64	1.36	-1.33	6.90	9.86	5.24
37.67	1.36	-1.33	6.90	9.87	5.23
37.69	1.36	-1.33	6.90	9.87	5.23
37.72	1.37	-1.33	6.89	9.87	5.23
37.75	1.37	-1.33	6.89	9.88	5.22
37.78	1.37	-1.33	6.89	9.87	5.23
37.81	1.37	-1.33	6.89	9.87	5.23
37.83	1.37	-1.33	6.89	9.87	5.23
37.86	1.37	-1.34	6.89	9.87	5.23
37.89	1.37	-1.34	6.89	9.87	5.23
37.92	1.37	-1.34	6.89	9.86	5.24
37.94	1.37	-1.34	6.89	9.87	5.23
37.97	1.37	-1.34	6.89	9.87	5.23
38.00	1.38	-1.34	6.89	9.87	5.23
38.03	1.38	-1.34	6.89	9.86	5.23
38.06	1.38	-1.35	6.89	9.86	5.24
38.08	1.38	-1.35	6.89	9.86	5.23
38.11	1.38	-1.35	6.89	9.86	5.24
38.14	1.38	-1.35	6.89	9.87	5.23
38.17	1.38	-1.35	6.88	9.86	5.23
38.19	1.38	-1.35	6.88	9.86	5.23
38.22	1.38	-1.35	6.89	9.87	5.23
38.25	1.38	-1.35	6.89	9.87	5.23
38.28	1.39	-1.35	6.88	9.86	5.23
38.31	1.39	-1.36	6.89	9.87	5.22
38.33	1.39	-1.36	6.88	9.86	5.23
38.36	1.39	-1.36	6.88	9.86	5.24
38.39	1.39	-1.36	6.88	9.86	5.23
38.42	1.39	-1.36	6.88	9.86	5.23
38.44	1.39	-1.36	6.88	9.86	5.23
38.47	1.39	-1.36	6.88	9.86	5.24
38.50	1.39	-1.37	6.88	9.85	5.24
38.53	1.39	-1.37	6.88	9.86	5.23
38.56	1.40	-1.37	6.88	9.87	5.22
38.58	1.40	-1.37	6.88	9.86	5.23
38.61	1.40	-1.37	6.88	9.85	5.24
38.64	1.40	-1.37	6.88	9.87	5.22
38.67	1.40	-1.37	6.88	9.87	5.22
38.69	1.40	-1.37	6.88	9.86	5.23
38.72	1.40	-1.37	6.88	9.87	5.22
38.75	1.40	-1.38	6.88	9.87	5.22
38.78	1.40	-1.38	6.88	9.88	5.22
38.81	1.40	-1.38	6.88	9.88	5.22
38.83	1.41	-1.38	6.88	9.86	5.24
38.86	1.41	-1.38	6.88	9.87	5.23
38.89	1.41	-1.38	6.88	9.87	5.23
38.92	1.41	-1.38	6.88	9.86	5.23
38.94	1.41	-1.39	6.88	9.86	5.23
38.97	1.41	-1.39	6.88	9.87	5.23
39.00	1.41	-1.39	6.88	9.87	5.22
39.03	1.41	-1.39	6.88	9.86	5.23
39.06	1.41	-1.39	6.88	9.86	5.23
39.08	1.42	-1.39	6.88	9.87	5.22
39.11	1.42	-1.39	6.88	9.86	5.23
39.14	1.42	-1.39	6.88	9.87	5.22
39.17	1.42	-1.40	6.87	9.87	5.22
39.19	1.42	-1.40	6.87	9.87	5.22
39.22	1.42	-1.40	6.87	9.87	5.22
39.25	1.42	-1.40	6.88	9.87	5.22
39.28	1.42	-1.40	6.87	9.87	5.22
39.31	1.42	-1.40	6.87	9.86	5.23
39.33	1.42	-1.40	6.88	9.87	5.22
39.36	1.43	-1.40	6.87	9.88	5.21
39.39	1.43	-1.41	6.87	9.87	5.22
39.42	1.43	-1.41	6.87	9.87	5.22
39.44	1.43	-1.41	6.87	9.87	5.22
39.47	1.43	-1.41	6.87	9.87	5.22
39.50	1.43	-1.41	6.87	9.87	5.22
39.53	1.43	-1.41	6.87	9.87	5.22
39.56	1.43	-1.41	6.87	9.87	5.22
39.58	1.43	-1.41	6.87	9.87	5.22
39.61	1.43	-1.42	6.87	9.88	5.21
39.64	1.44	-1.42	6.87	9.88	5.21
39.67	1.44	-1.42	6.87	9.88	5.21
39.69	1.44	-1.42	6.87	9.87	5.22
39.72	1.44	-1.42	6.86	9.87	5.22
39.75	1.44	-1.42	6.87	9.87	5.22
39.78	1.44	-1.42	6.87	9.86	5.23
39.81	1.44	-1.42	6.86	9.88	5.21
39.83	1.44	-1.43	6.86	9.88	5.21
39.86	1.44	-1.43	6.86	9.87	5.22
39.89	1.44	-1.43	6.86	9.87	5.22
39.92	1.45	-1.43	6.86	9.87	5.22
39.94	1.45	-1.43	6.86	9.86	5.22
39.97	1.45	-1.43	6.86	9.87	5.22
40.00	1.45	-1.43	6.86	9.87	5.22
40.03	1.45	-1.43	6.86	9.88	5.21
40.06	1.45	-1.43	6.86	9.88	5.20
40.08	1.45	-1.44	6.86	9.88	5.21
40.11	1.45	-1.44	6.86	9.89	5.20
40.14	1.45	-1.44	6.86	9.89	5.20
40.17	1.45	-1.44	6.86	9.89	5.20
40.19	1.46	-1.44	6.86	9.88	5.20
40.22	1.46	-1.44	6.86	9.88	5.20
40.25	1.46	-1.44	6.86	9.88	5.21
40.28	1.46	-1.45	6.85	9.90	5.18
40.31	1.46	-1.45	6.85	9.89	5.20
40.33	1.46	-1.45	6.85	9.89	5.20
40.36	1.46	-1.45	6.85	9.87	5.21
40.39	1.46	-1.45	6.85	9.87	5.22
40.42	1.46	-1.45	6.85	9.87	5.21
40.44	1.46	-1.45	6.85	9.87	5.21
40.47	1.47	-1.45	6.85	9.87	5.21