File: winhausen_data/OPA-Z30-10MPa_OPA10.txt
"time [h]"	"axial strain[%]"	"radial strain[%]"	"diff. stress[MPa]"	"eff. mean stress[MPa]"	"mean u[MPa]"
0.00	0.00	0.00	0.20	10.07	3.49
0.08	0.00	0.00	0.22	10.05	3.53
0.17	0.01	0.00	0.27	10.04	3.55
0.25	0.01	0.00	0.35	10.04	3.58
0.33	0.01	0.00	0.46	10.04	3.62
0.42	0.01	-0.01	0.66	10.02	3.70
0.50	0.02	-0.01	0.70	10.00	3.73
0.58	0.02	-0.01	0.77	10.00	3.76
0.67	0.02	-0.01	0.85	10.00	3.78
0.75	0.03	-0.01	0.94	9.98	3.83
0.83	0.03	-0.01	1.03	9.97	3.87
0.92	0.03	-0.01	1.11	9.95	3.92
1.00	0.04	-0.01	1.19	9.95	3.95
1.08	0.04	-0.02	1.28	9.93	4.00
1.17	0.04	-0.02	1.37	9.92	4.03
1.25	0.04	-0.02	1.47	9.91	4.08
1.33	0.05	-0.02	1.56	9.89	4.13
1.42	0.05	-0.02	1.65	9.88	4.17
1.50	0.05	-0.02	1.76	9.86	4.23
1.58	0.06	-0.02	1.87	9.85	4.28
1.67	0.06	-0.02	1.97	9.82	4.33
1.75	0.06	-0.03	2.07	9.80	4.39
1.83	0.07	-0.03	2.17	9.80	4.42
1.92	0.07	-0.03	2.27	9.78	4.47
2.00	0.07	-0.03	2.35	9.77	4.52
2.08	0.07	-0.03	2.45	9.76	4.56
2.17	0.08	-0.03	2.54	9.74	4.61
2.25	0.08	-0.04	2.62	9.71	4.67
2.33	0.08	-0.04	2.70	9.70	4.70
2.42	0.09	-0.04	2.76	9.69	4.73
2.50	0.09	-0.04	2.82	9.67	4.77
2.58	0.09	-0.04	2.88	9.64	4.82
2.67	0.09	-0.04	2.94	9.63	4.85
2.75	0.10	-0.04	3.02	9.63	4.88
2.83	0.10	-0.05	3.08	9.61	4.91
2.92	0.10	-0.05	3.13	9.59	4.95
3.00	0.11	-0.05	3.20	9.58	4.98
3.08	0.11	-0.05	3.25	9.56	5.03
3.17	0.11	-0.05	3.32	9.56	5.05
3.25	0.12	-0.05	3.37	9.53	5.10
3.33	0.12	-0.05	3.44	9.52	5.13
3.42	0.12	-0.05	3.49	9.51	5.16
3.50	0.12	-0.06	3.56	9.48	5.20
3.58	0.13	-0.06	3.61	9.47	5.23
3.67	0.13	-0.06	3.67	9.46	5.27
3.75	0.13	-0.06	3.73	9.46	5.28
3.83	0.14	-0.06	3.77	9.44	5.31
3.92	0.14	-0.06	3.83	9.43	5.35
4.00	0.14	-0.06	3.88	9.39	5.40
4.08	0.14	-0.06	3.94	9.38	5.44
4.17	0.15	-0.07	3.99	9.37	5.46
4.25	0.15	-0.07	4.05	9.36	5.49
4.33	0.15	-0.07	4.09	9.33	5.53
4.42	0.16	-0.07	4.14	9.32	5.57
4.50	0.16	-0.07	4.20	9.31	5.59
4.58	0.16	-0.07	4.25	9.29	5.62
4.67	0.17	-0.07	4.29	9.28	5.65
4.75	0.17	-0.08	4.35	9.27	5.68
4.83	0.17	-0.08	4.39	9.27	5.69
4.92	0.17	-0.08	4.44	9.25	5.73
5.00	0.18	-0.08	4.49	9.23	5.77
5.08	0.18	-0.08	4.54	9.22	5.79
5.17	0.18	-0.08	4.59	9.21	5.82
5.25	0.19	-0.08	4.64	9.20	5.85
5.33	0.19	-0.08	4.69	9.19	5.88
5.42	0.19	-0.09	4.73	9.17	5.90
5.50	0.20	-0.09	4.78	9.17	5.93
5.58	0.20	-0.09	4.82	9.15	5.96
5.67	0.20	-0.09	4.87	9.14	5.98
5.75	0.20	-0.09	4.91	9.13	6.01
5.83	0.21	-0.09	4.96	9.12	6.04
5.92	0.21	-0.09	5.01	9.11	6.06
6.00	0.21	-0.10	5.06	9.11	6.08
6.08	0.22	-0.10	5.09	9.09	6.10
6.17	0.22	-0.10	5.14	9.07	6.14
6.25	0.22	-0.10	5.19	9.06	6.17
6.33	0.22	-0.10	5.23	9.05	6.20
6.42	0.23	-0.10	5.27	9.04	6.22
6.50	0.23	-0.10	5.31	9.03	6.24
6.58	0.23	-0.11	5.35	9.02	6.26
6.67	0.24	-0.11	5.39	9.01	6.29
6.75	0.24	-0.11	5.44	9.00	6.31
6.83	0.24	-0.11	5.48	8.97	6.36
6.92	0.25	-0.11	5.52	8.98	6.37
7.00	0.25	-0.11	5.56	8.98	6.38
7.08	0.25	-0.11	5.61	8.95	6.42
7.17	0.25	-0.12	5.65	8.94	6.44
7.25	0.26	-0.12	5.69	8.93	6.47
7.33	0.26	-0.12	5.74	8.92	6.49
7.42	0.26	-0.12	5.77	8.92	6.51
7.50	0.27	-0.12	5.81	8.90	6.53
7.58	0.27	-0.12	5.85	8.89	6.56
7.67	0.27	-0.12	5.89	8.88	6.58
7.75	0.27	-0.13	5.93	8.88	6.60
7.83	0.28	-0.13	5.97	8.88	6.61
7.92	0.28	-0.13	6.00	8.85	6.65
8.00	0.28	-0.13	6.04	8.85	6.66
8.08	0.29	-0.13	6.07	8.83	6.69
8.17	0.29	-0.13	6.12	8.82	6.72
8.25	0.29	-0.13	6.15	8.82	6.73
8.33	0.30	-0.13	6.19	8.81	6.76
8.42	0.30	-0.14	6.24	8.80	6.78
8.50	0.30	-0.14	6.27	8.79	6.80
8.58	0.30	-0.14	6.31	8.78	6.82
8.67	0.31	-0.14	6.34	8.77	6.84
8.75	0.31	-0.14	6.37	8.76	6.87
8.83	0.31	-0.14	6.42	8.75	6.89
8.92	0.32	-0.15	6.45	8.75	6.90
9.00	0.32	-0.15	6.49	8.74	6.92
9.08	0.32	-0.15	6.53	8.73	6.95
9.17	0.33	-0.15	6.56	8.72	6.97
9.25	0.33	-0.15	6.59	8.71	6.99
9.33	0.33	-0.15	6.63	8.71	7.00
9.42	0.33	-0.15	6.66	8.70	7.02
9.50	0.34	-0.15	6.70	8.69	7.04
9.58	0.34	-0.16	6.73	8.69	7.05
9.67	0.34	-0.16	6.76	8.67	7.08
9.75	0.35	-0.16	6.80	8.67	7.10
9.83	0.35	-0.16	6.83	8.66	7.12
9.92	0.35	-0.16	6.85	8.65	7.13
10.00	0.35	-0.16	6.88	8.65	7.15
10.08	0.36	-0.17	6.93	8.65	7.17
10.17	0.36	-0.17	6.96	8.64	7.18
10.25	0.36	-0.17	7.00	8.63	7.20
10.33	0.37	-0.17	7.02	8.64	7.20
10.42	0.37	-0.17	7.05	8.63	7.22
10.50	0.37	-0.17	7.10	8.62	7.24
10.58	0.38	-0.17	7.13	8.61	7.27
10.67	0.38	-0.18	7.16	8.60	7.29
10.75	0.38	-0.18	7.19	8.60	7.30
10.83	0.38	-0.18	7.21	8.57	7.34
10.92	0.39	-0.18	7.24	8.59	7.33
11.00	0.39	-0.18	7.28	8.56	7.36
11.08	0.39	-0.18	7.32	8.57	7.37
11.17	0.40	-0.18	7.34	8.55	7.40
11.25	0.40	-0.19	7.37	8.56	7.39
11.33	0.40	-0.19	7.41	8.55	7.42
11.42	0.41	-0.19	7.43	8.54	7.43
11.50	0.41	-0.19	7.46	8.54	7.44
11.58	0.41	-0.19	7.50	8.55	7.46
11.67	0.41	-0.19	7.52	8.54	7.47
11.75	0.42	-0.19	7.56	8.53	7.50
11.83	0.42	-0.20	7.59	8.51	7.52
11.92	0.42	-0.20	7.62	8.50	7.54
12.00	0.43	-0.20	7.64	8.50	7.55
12.08	0.43	-0.20	7.68	8.50	7.56
12.17	0.43	-0.20	7.72	8.50	7.57
12.25	0.43	-0.20	7.75	8.49	7.59
12.33	0.44	-0.20	7.78	8.49	7.60
12.42	0.44	-0.21	7.80	8.49	7.61
12.50	0.443	-0.21	7.83	8.48	7.63
12.58	0.446	-0.21	7.85	8.47	7.65
12.67	0.449	-0.21	7.89	8.48	7.65
12.75	0.452	-0.21	7.92	8.46	7.68
12.83	0.46	-0.21	7.95	8.46	7.69
12.92	0.46	-0.22	7.98	8.46	7.70
13.00	0.461	-0.22	8.01	8.46	7.71
13.08	0.464	-0.22	8.03	8.43	7.75
13.17	0.47	-0.22	8.06	8.45	7.74
13.25	0.47	-0.22	8.09	8.45	7.75
13.33	0.47	-0.22	8.12	8.44	7.77
13.42	0.48	-0.22	8.14	8.44	7.77
13.50	0.48	-0.23	8.17	8.42	7.80
13.58	0.48	-0.23	8.20	8.43	7.80
13.67	0.48	-0.23	8.22	8.42	7.82
13.75	0.49	-0.23	8.25	8.41	7.84
13.83	0.49	-0.23	8.28	8.41	7.85
13.92	0.49	-0.23	8.30	8.41	7.86
14.00	0.50	-0.24	8.33	8.41	7.87
14.08	0.50	-0.24	8.35	8.39	7.89
14.17	0.50	-0.24	8.38	8.42	7.88
14.25	0.51	-0.24	8.41	8.40	7.90
14.33	0.51	-0.24	8.43	8.40	7.91
14.42	0.51	-0.24	8.45	8.40	7.92
14.50	0.51	-0.24	8.47	8.39	7.93
14.58	0.52	-0.25	8.50	8.38	7.95
14.67	0.52	-0.25	8.53	8.39	7.96
14.75	0.52	-0.25	8.55	8.38	7.97
14.83	0.53	-0.25	8.57	8.37	7.98
14.92	0.53	-0.25	8.61	8.38	7.99
15.00	0.53	-0.25	8.64	8.37	8.00
15.08	0.54	-0.26	8.65	8.37	8.01
15.17	0.54	-0.26	8.68	8.39	8.00
15.25	0.54	-0.26	8.71	8.37	8.04
15.33	0.54	-0.26	8.74	8.36	8.05
15.42	0.55	-0.26	8.75	8.37	8.05
15.50	0.55	-0.26	8.78	8.36	8.07
15.58	0.55	-0.27	8.81	8.37	8.07
15.67	0.56	-0.27	8.82	8.36	8.08
15.75	0.56	-0.27	8.85	8.36	8.09
15.83	0.56	-0.27	8.87	8.36	8.10
15.92	0.56	-0.27	8.90	8.37	8.09
16.00	0.57	-0.27	8.92	8.36	8.11
16.08	0.57	-0.27	8.94	8.35	8.13
16.17	0.57	-0.28	8.97	8.36	8.13
16.25	0.58	-0.28	8.99	8.35	8.15
16.33	0.58	-0.28	9.01	8.35	8.15
16.42	0.58	-0.28	9.03	8.35	8.16
16.50	0.59	-0.28	9.05	8.34	8.18
16.58	0.59	-0.28	9.08	8.34	8.18
16.67	0.59	-0.29	9.10	8.33	8.20
16.75	0.59	-0.29	9.12	8.35	8.19
16.83	0.60	-0.29	9.15	8.34	8.21
16.92	0.60	-0.29	9.17	8.35	8.21
17.00	0.60	-0.29	9.19	8.34	8.22
17.08	0.61	-0.29	9.22	8.34	8.23
17.17	0.61	-0.30	9.24	8.34	8.24
17.25	0.61	-0.30	9.25	8.33	8.25
17.33	0.61	-0.30	9.28	8.33	8.26
17.42	0.62	-0.30	9.30	8.33	8.27
17.50	0.62	-0.30	9.33	8.34	8.27
17.58	0.62	-0.30	9.34	8.35	8.27
17.67	0.63	-0.31	9.37	8.33	8.29
17.75	0.63	-0.31	9.38	8.33	8.30
17.83	0.63	-0.31	9.41	8.33	8.31
17.92	0.64	-0.31	9.43	8.34	8.30
18.00	0.64	-0.31	9.44	8.33	8.32
18.08	0.64	-0.31	9.47	8.33	8.32
18.17	0.64	-0.32	9.50	8.34	8.33
18.25	0.65	-0.32	9.51	8.34	8.33
18.33	0.65	-0.32	9.54	8.34	8.34
18.42	0.65	-0.32	9.56	8.34	8.35
18.50	0.66	-0.32	9.57	8.33	8.36
18.58	0.66	-0.32	9.60	8.32	8.38
18.67	0.66	-0.33	9.62	8.33	8.37
18.75	0.67	-0.33	9.64	8.33	8.38
18.83	0.67	-0.33	9.66	8.33	8.39
18.92	0.67	-0.33	9.67	8.35	8.38
19.00	0.67	-0.33	9.69	8.33	8.40
19.08	0.68	-0.33	9.71	8.30	8.44
19.17	0.68	-0.34	9.73	8.40	8.34
19.25	0.68	-0.34	9.75	8.36	8.39
19.33	0.69	-0.34	9.77	8.36	8.40
19.42	0.69	-0.34	9.79	8.37	8.39
19.50	0.69	-0.34	9.81	8.38	8.39
19.58	0.69	-0.34	9.83	8.37	8.41
19.67	0.70	-0.35	9.84	8.38	8.40
19.75	0.70	-0.35	9.86	8.30	8.48
19.83	0.70	-0.35	9.89	8.36	8.44
19.92	0.71	-0.35	9.91	8.37	8.44
20.00	0.71	-0.35	9.92	8.40	8.41
20.08	0.71	-0.35	9.95	8.38	8.43
20.17	0.72	-0.36	9.95	8.37	8.45
20.25	0.72	-0.36	9.98	8.36	8.46
20.33	0.72	-0.36	10.00	8.35	8.48
20.42	0.72	-0.36	10.01	8.36	8.48
20.50	0.73	-0.36	10.03	8.38	8.47
20.58	0.73	-0.37	10.06	8.37	8.48
20.67	0.73	-0.37	10.07	8.38	8.48
20.75	0.74	-0.37	10.09	8.39	8.47
20.83	0.74	-0.37	10.10	8.38	8.49
20.92	0.74	-0.37	10.12	8.36	8.51
21.00	0.75	-0.37	10.14	8.36	8.52
21.08	0.75	-0.38	10.16	8.36	8.52
21.17	0.75	-0.38	10.18	8.38	8.52
21.25	0.75	-0.38	10.20	8.36	8.54
21.33	0.76	-0.38	10.21	8.37	8.54
21.42	0.76	-0.38	10.21	8.36	8.54
21.50	0.76	-0.38	10.24	8.37	8.54
21.58	0.77	-0.39	10.26	8.38	8.54
21.67	0.77	-0.39	10.28	8.38	8.55
21.75	0.77	-0.39	10.30	8.38	8.55
21.83	0.77	-0.39	10.31	8.38	8.56
21.92	0.78	-0.39	10.32	8.38	8.56
22.00	0.78	-0.39	10.35	8.38	8.57
22.08	0.78	-0.40	10.36	8.39	8.57
22.17	0.79	-0.40	10.38	8.39	8.57
22.25	0.79	-0.40	10.40	8.40	8.57
22.33	0.79	-0.40	10.41	8.40	8.57
22.42	0.80	-0.40	10.43	8.41	8.57
22.50	0.80	-0.41	10.45	8.40	8.58
22.58	0.80	-0.41	10.46	8.41	8.58
22.67	0.80	-0.41	10.48	8.41	8.58
22.75	0.81	-0.41	10.48	8.41	8.58
22.83	0.81	-0.41	10.51	8.42	8.58
22.92	0.81	-0.41	10.52	8.41	8.59
23.00	0.82	-0.42	10.54	8.42	8.60
23.08	0.82	-0.42	10.56	8.42	8.60
23.17	0.82	-0.42	10.57	8.42	8.61
23.25	0.82	-0.42	10.59	8.42	8.61
23.33	0.83	-0.42	10.60	8.43	8.60
23.42	0.83	-0.42	10.61	8.43	8.61
23.50	0.83	-0.43	10.63	8.44	8.60
23.58	0.84	-0.43	10.65	8.44	8.61
23.67	0.84	-0.43	10.66	8.45	8.61
23.75	0.84	-0.43	10.68	8.45	8.61
23.83	0.85	-0.43	10.69	8.45	8.61
23.92	0.85	-0.43	10.70	8.46	8.61
24.00	0.85	-0.44	10.73	8.46	8.62
24.08	0.85	-0.44	10.74	8.47	8.61
24.17	0.86	-0.44	10.75	8.46	8.62
24.25	0.86	-0.44	10.77	8.47	8.62
24.33	0.86	-0.44	10.78	8.48	8.62
24.42	0.87	-0.45	10.79	8.48	8.62
24.50	0.87	-0.45	10.81	8.49	8.62
24.58	0.87	-0.45	10.83	8.47	8.64
24.67	0.88	-0.45	10.82	8.47	8.64
24.75	0.88	-0.45	10.86	8.50	8.62
24.83	0.88	-0.45	10.86	8.50	8.62
24.92	0.88	-0.46	10.87	8.50	8.63
25.00	0.89	-0.46	10.89	8.51	8.62
25.08	0.89	-0.46	10.89	8.47	8.66
25.17	0.89	-0.46	10.90	8.53	8.60
25.25	0.90	-0.46	10.92	8.56	8.58
25.33	0.90	-0.46	10.92	8.57	8.57
25.42	0.90	-0.47	10.92	8.55	8.59
25.50	0.90	-0.47	10.93	8.48	8.66
25.58	0.91	-0.47	10.94	8.57	8.58
25.67	0.91	-0.47	10.94	8.51	8.64
25.75	0.91	-0.47	10.94	8.54	8.61
25.83	0.92	-0.47	10.92	8.54	8.60
25.91	0.92	-0.47	10.92	8.56	8.57
25.99	0.92	-0.48	10.89	8.57	8.56
26.08	0.93	-0.48	10.89	8.54	8.59
26.16	0.93	-0.48	10.86	8.56	8.57
26.24	0.93	-0.48	10.83	8.56	8.55
26.33	0.93	-0.48	10.77	8.56	8.53
26.41	0.94	-0.48	10.72	8.57	8.50
26.49	0.94	-0.48	10.65	8.56	8.49
26.58	0.94	-0.48	10.56	8.56	8.46
26.66	0.95	-0.48	10.47	8.57	8.42
26.74	0.95	-0.49	10.37	8.55	8.41
26.83	0.95	-0.50	10.23	8.56	8.35
26.91	0.95	-0.50	10.04	8.51	8.34
26.99	0.96	-0.52	9.85	8.52	8.26
27.08	0.96	-0.53	9.71	8.53	8.21
27.16	0.96	-0.54	9.62	8.55	8.15
27.24	0.97	-0.55	9.54	8.55	8.13
27.33	0.97	-0.56	9.47	8.54	8.12
27.41	0.97	-0.57	9.36	8.61	8.01
27.49	0.98	-0.58	9.29	8.64	7.96
27.58	0.98	-0.59	9.24	8.63	7.95
27.66	0.98	-0.60	9.20	8.64	7.92
27.74	0.98	-0.61	9.16	8.64	7.91
27.83	0.99	-0.62	9.14	8.61	7.93
27.91	0.99	-0.62	9.13	8.68	7.87
27.99	0.99	-0.63	9.11	8.66	7.88
28.08	1.00	-0.64	9.09	8.69	7.84
28.16	1.00	-0.65	9.08	8.63	7.89
28.24	1.00	-0.65	9.06	8.74	7.79
28.33	1.00	-0.66	9.05	8.71	7.80
28.41	1.01	-0.67	9.04	8.69	7.82
28.49	1.01	-0.67	9.03	8.70	7.81
28.58	1.01	-0.68	9.02	8.72	7.79
28.66	1.02	-0.68	9.02	8.70	7.81
28.74	1.02	-0.69	9.01	8.78	7.73
28.83	1.02	-0.69	9.00	8.75	7.75
28.91	1.03	-0.70	8.99	8.77	7.72
28.99	1.03	-0.71	8.97	8.76	7.73
29.08	1.03	-0.71	8.96	8.76	7.73
29.16	1.03	-0.72	8.95	8.79	7.70
29.24	1.04	-0.72	8.94	8.79	7.69
29.33	1.04	-0.73	8.92	8.77	7.71
29.41	1.04	-0.73	8.91	8.80	7.67
29.49	1.05	-0.74	8.88	8.80	7.66
29.58	1.05	-0.74	8.88	8.82	7.64
29.66	1.05	-0.75	8.87	8.82	7.64
29.74	1.06	-0.75	8.86	8.82	7.63
29.83	1.06	-0.76	8.84	8.80	7.65
29.91	1.06	-0.76	8.84	8.83	7.62
29.99	1.06	-0.77	8.83	8.83	7.61
30.08	1.07	-0.77	8.81	8.85	7.59
30.16	1.07	-0.78	8.82	8.77	7.66
30.24	1.07	-0.78	8.81	8.86	7.58
30.33	1.08	-0.79	8.81	8.85	7.59
30.41	1.08	-0.79	8.80	8.84	7.59
30.49	1.08	-0.80	8.80	8.83	7.60
30.58	1.08	-0.80	8.79	8.90	7.53
30.66	1.09	-0.81	8.79	8.89	7.54
30.74	1.09	-0.81	8.79	8.89	7.54
30.83	1.09	-0.82	8.79	8.89	7.54
30.91	1.10	-0.82	8.78	8.83	7.60
30.99	1.10	-0.82	8.78	8.92	7.51
31.08	1.10	-0.83	8.78	8.94	7.49
31.16	1.11	-0.83	8.77	8.84	7.58
31.24	1.11	-0.84	8.77	8.94	7.48
31.33	1.11	-0.84	8.77	8.96	7.46
31.41	1.11	-0.85	8.77	8.93	7.49
31.49	1.12	-0.85	8.76	8.88	7.54
31.58	1.12	-0.86	8.75	8.88	7.53
31.66	1.12	-0.86	8.75	8.96	7.46
31.74	1.13	-0.87	8.73	8.91	7.50
31.83	1.13	-0.87	8.73	8.93	7.48
31.91	1.13	-0.87	8.72	8.99	7.42
31.99	1.14	-0.88	8.71	8.95	7.46
32.08	1.14	-0.88	8.67	8.93	7.46
32.16	1.14	-0.89	8.63	8.97	7.41
32.24	1.14	-0.89	8.57	8.96	7.39
32.33	1.15	-0.90	8.53	8.88	7.47
32.41	1.15	-0.90	8.50	8.95	7.38
32.49	1.15	-0.91	8.50	8.89	7.44
32.58	1.16	-0.91	8.49	8.98	7.34
32.66	1.16	-0.92	8.47	8.98	7.35
32.74	1.16	-0.92	8.47	8.95	7.37
32.83	1.16	-0.92	8.45	8.95	7.36
32.91	1.17	-0.93	8.44	8.98	7.33
32.99	1.17	-0.93	8.43	9.00	7.31
33.08	1.17	-0.94	8.43	8.95	7.36
33.16	1.18	-0.94	8.42	8.98	7.33
33.24	1.18	-0.95	8.41	8.96	7.35
33.33	1.18	-0.95	8.41	8.97	7.33
33.41	1.19	-0.95	8.40	8.99	7.30
33.49	1.19	-0.96	8.39	8.98	7.32
33.58	1.19	-0.96	8.38	8.98	7.31
33.66	1.19	-0.97	8.38	8.96	7.34
33.74	1.20	-0.97	8.38	8.99	7.30
33.83	1.20	-0.97	8.37	8.95	7.34
33.91	1.20	-0.98	8.36	8.99	7.30
33.99	1.21	-0.98	8.36	9.00	7.28
34.08	1.21	-0.99	8.36	8.99	7.30
34.16	1.21	-0.99	8.35	9.04	7.24
34.24	1.21	-0.99	8.35	9.00	7.29
34.33	1.22	-1.00	8.36	9.00	7.29
34.41	1.22	-1.00	8.35	9.00	7.28
34.49	1.22	-1.01	8.36	9.03	7.26
34.58	1.23	-1.01	8.34	9.02	7.26
34.66	1.23	-1.01	8.34	9.02	7.26
34.74	1.23	-1.02	8.34	8.97	7.31
34.83	1.24	-1.02	8.34	9.05	7.23
34.91	1.24	-1.03	8.34	9.02	7.26
34.99	1.24	-1.03	8.35	9.02	7.27
35.08	1.24	-1.03	8.34	9.05	7.23
35.16	1.25	-1.04	8.34	8.98	7.30
35.24	1.25	-1.04	8.33	9.05	7.23
35.33	1.25	-1.04	8.33	9.08	7.20
35.41	1.26	-1.05	8.34	9.06	7.22
35.49	1.26	-1.05	8.34	9.04	7.24
35.58	1.26	-1.06	8.33	9.05	7.23
35.66	1.27	-1.06	8.33	9.00	7.27
35.74	1.27	-1.06	8.34	9.09	7.19
35.83	1.27	-1.07	8.34	9.09	7.18
35.91	1.27	-1.07	8.34	9.09	7.19
35.99	1.28	-1.07	8.33	9.09	7.18
36.08	1.28	-1.08	8.33	9.02	7.26
36.16	1.28	-1.08	8.34	9.10	7.17
36.24	1.29	-1.09	8.34	9.09	7.19
36.33	1.29	-1.09	8.34	9.09	7.20
36.41	1.29	-1.09	8.32	9.07	7.21
36.49	1.29	-1.10	8.33	9.09	7.19
36.58	1.30	-1.10	8.33	9.11	7.16
36.66	1.30	-1.10	8.34	9.10	7.17
36.74	1.30	-1.11	8.34	9.11	7.17
36.83	1.31	-1.11	8.34	9.04	7.24
36.91	1.31	-1.11	8.33	9.12	7.16
36.99	1.31	-1.12	8.33	9.12	7.16
37.08	1.32	-1.12	8.34	9.09	7.19
37.16	1.32	-1.12	8.34	9.14	7.14
37.24	1.32	-1.13	8.34	9.07	7.21
37.33	1.32	-1.13	8.34	9.06	7.22
37.41	1.33	-1.13	8.33	9.10	7.17
37.49	1.33	-1.14	8.34	9.09	7.19
37.58	1.33	-1.14	8.33	9.12	7.16
37.66	1.34	-1.14	8.34	9.11	7.17
37.74	1.34	-1.15	8.33	9.13	7.15
37.83	1.34	-1.15	8.34	9.13	7.15
37.91	1.34	-1.15	8.33	9.14	7.14
37.99	1.35	-1.15	8.34	9.10	7.19
38.08	1.35	-1.16	8.35	9.11	7.17
38.16	1.35	-1.16	8.35	9.06	7.23
38.24	1.36	-1.16	8.34	9.10	7.18
38.33	1.36	-1.17	8.35	9.06	7.22
38.41	1.36	-1.17	8.35	9.14	7.14
38.49	1.37	-1.17	8.34	9.13	7.14
38.58	1.37	-1.18	8.34	9.14	7.14
38.66	1.37	-1.18	8.34	9.13	7.15
38.74	1.37	-1.18	8.34	9.13	7.15
38.83	1.38	-1.19	8.34	9.15	7.13
38.91	1.38	-1.19	8.34	9.09	7.19
38.99	1.38	-1.19	8.35	9.13	7.15
39.08	1.39	-1.19	8.33	9.12	7.16
39.16	1.39	-1.20	8.34	9.18	7.10
39.24	1.39	-1.20	8.34	9.11	7.17
39.33	1.40	-1.20	8.34	9.12	7.15
39.41	1.40	-1.21	8.33	9.15	7.13
39.49	1.40	-1.21	8.32	9.14	7.13
39.58	1.40	-1.21	8.32	9.15	7.12
39.66	1.41	-1.21	8.31	9.12	7.15
39.74	1.41	-1.22	8.30	9.12	7.14
39.83	1.41	-1.22	8.30	9.15	7.11
39.91	1.42	-1.22	8.29	9.11	7.15
39.99	1.42	-1.23	8.28	9.15	7.11
40.08	1.42	-1.23	8.28	9.14	7.12
40.16	1.42	-1.23	8.28	9.14	7.12
40.24	1.43	-1.23	8.28	9.17	7.09
40.33	1.43	-1.24	8.28	9.14	7.12
40.41	1.43	-1.24	8.28	9.13	7.13
40.49	1.44	-1.24	8.27	9.14	7.12
40.58	1.44	-1.24	8.28	9.17	7.09
40.66	1.44	-1.25	8.27	9.15	7.10
40.74	1.45	-1.25	8.26	9.14	7.12
40.83	1.45	-1.25	8.26	9.14	7.12
40.91	1.45	-1.26	8.26	9.16	7.09
40.99	1.45	-1.26	8.26	9.10	7.15
41.08	1.46	-1.26	8.27	9.19	7.07
41.16	1.46	-1.26	8.27	9.18	7.08
41.24	1.46	-1.27	8.27	9.19	7.07
41.33	1.47	-1.27	8.27	9.14	7.11
41.41	1.47	-1.27	8.26	9.14	7.12
41.49	1.47	-1.28	8.26	9.17	7.08
41.58	1.48	-1.28	8.27	9.17	7.09
41.66	1.48	-1.28	8.27	9.15	7.10
41.74	1.48	-1.28	8.27	9.11	7.14
41.83	1.48	-1.29	8.27	9.13	7.13
41.91	1.49	-1.29	8.27	9.20	7.05
41.99	1.49	-1.29	8.27	9.19	7.06
42.08	1.49	-1.30	8.27	9.19	7.07
42.16	1.50	-1.30	8.27	9.15	7.10
42.24	1.50	-1.30	8.27	9.21	7.05
42.33	1.50	-1.30	8.26	9.20	7.06
42.41	1.50	-1.31	8.27	9.19	7.06
42.49	1.51	-1.31	8.28	9.22	7.04
42.58	1.51	-1.31	8.28	9.14	7.12
42.66	1.51	-1.31	8.27	9.21	7.05
42.74	1.52	-1.32	8.28	9.20	7.06
42.83	1.52	-1.32	8.28	9.19	7.07
42.91	1.52	-1.32	8.28	9.19	7.07
42.99	1.53	-1.32	8.27	9.13	7.13
43.08	1.53	-1.32	8.28	9.23	7.02
43.16	1.53	-1.33	8.29	9.22	7.04
43.24	1.53	-1.33	8.27	9.17	7.08
43.33	1.54	-1.33	8.27	9.23	7.03
43.41	1.54	-1.33	8.28	9.13	7.13
43.49	1.54	-1.34	8.28	9.23	7.03
43.58	1.55	-1.34	8.28	9.26	7.00
43.66	1.55	-1.34	8.28	9.20	7.06
43.74	1.55	-1.34	8.28	9.15	7.11
43.83	1.55	-1.35	8.26	9.22	7.03
43.91	1.56	-1.35	8.28	9.20	7.06
43.99	1.56	-1.35	8.28	9.25	7.01
44.08	1.56	-1.35	8.29	9.26	7.01
44.16	1.57	-1.35	8.29	9.15	7.11
44.24	1.57	-1.36	8.28	9.21	7.05
44.33	1.57	-1.36	8.27	9.22	7.04
44.41	1.58	-1.36	8.28	9.19	7.07
44.49	1.58	-1.36	8.27	9.20	7.06
44.58	1.58	-1.36	8.28	9.21	7.05
44.66	1.58	-1.37	8.27	9.15	7.11
44.74	1.59	-1.37	8.28	9.20	7.06
44.83	1.59	-1.37	8.29	9.23	7.03
44.91	1.59	-1.37	8.28	9.21	7.05
44.99	1.60	-1.38	8.30	9.14	7.13
45.08	1.60	-1.38	8.29	9.29	6.98
45.16	1.60	-1.38	8.28	9.24	7.02
45.24	1.61	-1.38	8.29	9.23	7.03
45.33	1.61	-1.38	8.28	9.22	7.04
45.41	1.61	-1.39	8.29	9.21	7.05
45.49	1.61	-1.39	8.29	9.24	7.02
45.58	1.62	-1.39	8.30	9.28	6.99
45.66	1.62	-1.39	8.30	9.26	7.00
45.74	1.62	-1.39	8.30	9.25	7.02
45.83	1.63	-1.40	8.30	9.24	7.03
45.91	1.63	-1.40	8.30	9.21	7.05
45.99	1.63	-1.40	8.29	9.17	7.09
46.08	1.63	-1.40	8.29	9.26	7.01
46.16	1.64	-1.41	8.29	9.24	7.02
46.24	1.64	-1.41	8.30	9.24	7.02
46.33	1.64	-1.41	8.30	9.26	7.00
46.41	1.65	-1.41	8.29	9.27	6.99
46.49	1.65	-1.41	8.30	9.25	7.02
46.58	1.65	-1.42	8.30	9.24	7.03
46.66	1.66	-1.42	8.29	9.28	6.98
46.74	1.66	-1.42	8.30	9.25	7.02
46.83	1.66	-1.42	8.30	9.17	7.09
46.91	1.66	-1.42	8.30	9.26	7.00
46.99	1.67	-1.43	8.30	9.25	7.02
47.08	1.67	-1.43	8.31	9.28	6.99
47.16	1.67	-1.43	8.30	9.28	6.99
47.24	1.68	-1.43	8.31	9.19	7.08
47.33	1.68	-1.43	8.30	9.29	6.98
47.41	1.68	-1.43	8.31	9.29	6.98
47.49	1.68	-1.44	8.31	9.26	7.01
47.58	1.69	-1.44	8.30	9.26	7.01
47.66	1.69	-1.44	8.31	9.30	6.97
47.74	1.69	-1.44	8.30	9.20	7.06
47.83	1.70	-1.44	8.31	9.29	6.98
47.91	1.70	-1.45	8.32	9.21	7.07
47.99	1.70	-1.45	8.31	9.33	6.94
48.08	1.71	-1.45	8.32	9.28	6.99
48.16	1.71	-1.45	8.31	9.30	6.97
48.24	1.71	-1.45	8.32	9.32	6.95
48.33	1.71	-1.46	8.32	9.28	7.00
48.41	1.72	-1.46	8.32	9.25	7.02
48.49	1.72	-1.46	8.32	9.29	6.99
48.58	1.72	-1.46	8.32	9.31	6.96
48.66	1.73	-1.46	8.33	9.30	6.98
48.74	1.73	-1.47	8.32	9.30	6.97
48.83	1.73	-1.47	8.33	9.31	6.97
48.91	1.74	-1.47	8.32	9.27	7.00
48.99	1.74	-1.47	8.33	9.20	7.08
49.08	1.74	-1.47	8.33	9.29	6.99
49.16	1.74	-1.48	8.33	9.28	7.00
49.24	1.75	-1.48	8.32	9.27	7.00
49.33	1.75	-1.48	8.34	9.27	7.01
49.41	1.75	-1.48	8.32	9.31	6.96
49.49	1.76	-1.48	8.33	9.24	7.03
49.58	1.76	-1.49	8.33	9.24	7.03
49.66	1.76	-1.49	8.33	9.29	6.98
49.74	1.76	-1.49	8.33	9.25	7.03
49.83	1.77	-1.49	8.33	9.23	7.04
49.91	1.77	-1.49	8.33	9.34	6.94
49.99	1.77	-1.50	8.33	9.31	6.97
50.08	1.78	-1.50	8.33	9.29	6.98
50.16	1.78	-1.50	8.33	9.31	6.97
50.24	1.78	-1.50	8.34	9.31	6.97
50.33	1.79	-1.50	8.35	9.25	7.03
50.41	1.79	-1.51	8.33	9.33	6.94
50.49	1.79	-1.51	8.35	9.25	7.04
50.58	1.79	-1.51	8.35	9.27	7.01
50.66	1.80	-1.51	8.34	9.24	7.04
50.74	1.80	-1.52	8.35	9.31	6.98
50.83	1.80	-1.52	8.35	9.29	6.99
50.91	1.81	-1.52	8.35	9.29	6.99
50.99	1.81	-1.52	8.36	9.27	7.01
51.08	1.81	-1.52	8.36	9.33	6.95
51.16	1.81	-1.53	8.36	9.30	6.99
51.24	1.82	-1.53	8.36	9.35	6.94
51.33	1.82	-1.53	8.37	9.29	7.00
51.41	1.82	-1.53	8.37	9.26	7.03
51.49	1.83	-1.53	8.36	9.37	6.92
51.58	1.83	-1.54	8.37	9.32	6.98
51.66	1.83	-1.54	8.37	9.32	6.97
51.74	1.84	-1.54	8.38	9.35	6.94
51.83	1.84	-1.54	8.37	9.28	7.01
51.91	1.84	-1.54	8.37	9.29	7.00
51.99	1.84	-1.55	8.38	9.31	6.98
52.08	1.85	-1.55	8.37	9.35	6.94
52.16	1.85	-1.55	8.37	9.34	6.95
52.24	1.85	-1.55	8.38	9.35	6.95
52.33	1.86	-1.55	8.38	9.31	6.98
52.41	1.86	-1.56	8.38	9.38	6.91
52.49	1.86	-1.56	8.38	9.33	6.96
52.58	1.87	-1.56	8.39	9.34	6.96
52.66	1.87	-1.56	8.39	9.36	6.94
52.74	1.87	-1.57	8.38	9.30	7.00
52.83	1.87	-1.57	8.38	9.29	7.00
52.91	1.88	-1.57	8.37	9.36	6.93
52.99	1.88	-1.57	8.39	9.32	6.98
53.08	1.88	-1.57	8.39	9.32	6.98
53.16	1.89	-1.58	8.39	9.36	6.93
53.24	1.89	-1.58	8.40	9.26	7.04
53.33	1.89	-1.58	8.38	9.34	6.95
53.41	1.89	-1.58	8.40	9.33	6.97
53.49	1.90	-1.58	8.40	9.36	6.93
53.58	1.90	-1.59	8.40	9.32	6.98
53.66	1.90	-1.59	8.41	9.33	6.97
53.74	1.91	-1.59	8.40	9.38	6.92
53.83	1.91	-1.59	8.41	9.36	6.95
53.91	1.91	-1.59	8.39	9.39	6.91
53.99	1.92	-1.60	8.41	9.30	7.00
54.08	1.92	-1.60	8.41	9.30	7.00
54.16	1.92	-1.60	8.40	9.38	6.92
54.24	1.92	-1.60	8.41	9.36	6.95
54.33	1.93	-1.61	8.42	9.37	6.94
54.41	1.93	-1.61	8.42	9.34	6.97
54.49	1.93	-1.61	8.42	9.32	6.99
54.58	1.94	-1.61	8.43	9.33	6.98
54.66	1.94	-1.61	8.42	9.32	6.99
54.74	1.94	-1.62	8.43	9.37	6.94
54.83	1.95	-1.62	8.43	9.37	6.94
54.91	1.95	-1.62	8.42	9.36	6.95
54.99	1.95	-1.62	8.42	9.38	6.93
55.08	1.95	-1.62	8.43	9.34	6.97
55.16	1.96	-1.63	8.43	9.36	6.95
55.24	1.96	-1.63	8.44	9.34	6.97
55.33	1.96	-1.63	8.43	9.41	6.90
55.41	1.97	-1.63	8.44	9.36	6.95
55.49	1.97	-1.64	8.44	9.34	6.98
55.58	1.97	-1.64	8.45	9.37	6.94
55.66	1.97	-1.64	8.45	9.37	6.95
55.74	1.98	-1.64	8.45	9.35	6.96
55.83	1.98	-1.64	8.45	9.36	6.95
55.91	1.98	-1.65	8.45	9.39	6.93
55.99	1.99	-1.65	8.45	9.34	6.98
56.08	1.99	-1.65	8.46	9.35	6.97
56.16	1.99	-1.65	8.46	9.31	7.00
56.24	2.00	-1.66	8.45	9.42	6.90
56.33	2.00	-1.66	8.46	9.39	6.93
56.41	2.00	-1.66	8.47	9.37	6.95
56.49	2.00	-1.66	8.46	9.36	6.97
56.58	2.01	-1.66	8.46	9.36	6.96
56.66	2.01	-1.67	8.47	9.39	6.93
56.74	2.01	-1.67	8.47	9.34	6.99
56.83	2.02	-1.67	8.47	9.39	6.93
56.91	2.02	-1.67	8.47	9.38	6.94
56.99	2.02	-1.68	8.48	9.32	7.01
57.08	2.02	-1.68	8.46	9.40	6.92
57.16	2.03	-1.68	8.48	9.38	6.94
57.24	2.03	-1.68	8.47	9.40	6.92
57.33	2.03	-1.68	8.48	9.35	6.97
57.41	2.04	-1.69	8.47	9.35	6.98
57.49	2.04	-1.69	8.49	9.39	6.93
57.58	2.04	-1.69	8.49	9.38	6.95
57.66	2.05	-1.69	8.48	9.39	6.94
57.74	2.05	-1.70	8.48	9.41	6.92
57.83	2.05	-1.70	8.48	9.39	6.94
57.91	2.05	-1.70	8.49	9.34	6.99
57.99	2.06	-1.70	8.49	9.38	6.95
58.08	2.06	-1.71	8.50	9.37	6.97
58.16	2.06	-1.71	8.49	9.37	6.97
58.24	2.07	-1.71	8.49	9.39	6.94
58.33	2.07	-1.71	8.50	9.35	6.98
58.41	2.07	-1.71	8.49	9.38	6.95
58.49	2.08	-1.72	8.50	9.36	6.97
58.58	2.08	-1.72	8.50	9.40	6.94
58.66	2.08	-1.72	8.50	9.39	6.94
58.74	2.08	-1.72	8.51	9.39	6.94
58.83	2.09	-1.73	8.50	9.39	6.94
58.91	2.09	-1.73	8.51	9.41	6.93
58.99	2.09	-1.73	8.51	9.40	6.94
59.08	2.10	-1.73	8.49	9.40	6.93
59.16	2.10	-1.73	8.51	9.42	6.92
59.24	2.10	-1.74	8.52	9.41	6.93
59.33	2.10	-1.74	8.51	9.38	6.96
59.41	2.11	-1.74	8.51	9.41	6.93
59.49	2.11	-1.74	8.51	9.43	6.91
59.58	2.11	-1.75	8.52	9.42	6.92
59.66	2.12	-1.75	8.51	9.40	6.94
59.74	2.12	-1.75	8.51	9.40	6.94
59.83	2.12	-1.75	8.51	9.36	6.98
59.91	2.13	-1.76	8.51	9.43	6.91
59.99	2.13	-1.76	8.52	9.42	6.92
60.08	2.13	-1.76	8.52	9.41	6.93
60.16	2.13	-1.76	8.51	9.44	6.90
60.24	2.14	-1.76	8.52	9.40	6.94
60.33	2.14	-1.77	8.52	9.40	6.94
60.41	2.14	-1.77	8.52	9.40	6.94
60.49	2.15	-1.77	8.52	9.40	6.94
60.58	2.15	-1.77	8.53	9.36	6.98
60.66	2.15	-1.78	8.53	9.43	6.91
60.74	2.15	-1.78	8.52	9.43	6.92
60.83	2.16	-1.78	8.52	9.43	6.91
60.91	2.16	-1.78	8.53	9.41	6.93
60.99	2.16	-1.79	8.53	9.43	6.91
61.08	2.17	-1.79	8.53	9.41	6.94
61.16	2.17	-1.79	8.53	9.41	6.94
61.24	2.17	-1.79	8.54	9.42	6.93
61.33	2.18	-1.79	8.54	9.37	6.98
61.41	2.18	-1.80	8.53	9.46	6.89
61.49	2.18	-1.80	8.54	9.44	6.90
61.58	2.18	-1.80	8.52	9.46	6.88
61.66	2.19	-1.80	8.53	9.40	6.95
61.74	2.19	-1.81	8.53	9.42	6.92
61.83	2.19	-1.81	8.53	9.38	6.97
61.91	2.20	-1.81	8.53	9.43	6.91
61.99	2.20	-1.81	8.53	9.45	6.89
62.08	2.20	-1.82	8.54	9.41	6.94
62.16	2.21	-1.82	8.53	9.37	6.97
62.24	2.21	-1.82	8.54	9.48	6.87
62.33	2.21	-1.82	8.53	9.46	6.89
62.41	2.21	-1.82	8.53	9.45	6.90
62.49	2.22	-1.83	8.53	9.43	6.91
62.58	2.22	-1.83	8.53	9.38	6.96
62.66	2.22	-1.83	8.54	9.46	6.88
62.74	2.23	-1.83	8.54	9.45	6.90
62.83	2.23	-1.84	8.54	9.47	6.88
62.91	2.23	-1.84	8.53	9.43	6.91
62.99	2.23	-1.84	8.54	9.46	6.89
63.08	2.24	-1.84	8.55	9.42	6.93
63.16	2.24	-1.85	8.53	9.42	6.93
63.24	2.24	-1.85	8.54	9.44	6.91
63.33	2.25	-1.85	8.54	9.40	6.95
63.41	2.25	-1.85	8.54	9.47	6.88
63.49	2.25	-1.85	8.55	9.46	6.89
63.58	2.26	-1.86	8.55	9.40	6.95
63.66	2.26	-1.86	8.55	9.47	6.88
63.74	2.26	-1.86	8.55	9.47	6.88
63.83	2.26	-1.86	8.55	9.48	6.86
63.91	2.27	-1.87	8.54	9.45	6.90
63.99	2.27	-1.87	8.55	9.47	6.88
64.08	2.27	-1.87	8.55	9.42	6.93
64.16	2.28	-1.87	8.54	9.48	6.87
64.24	2.28	-1.87	8.55	9.47	6.88
64.33	2.28	-1.88	8.55	9.46	6.89
64.41	2.29	-1.88	8.54	9.46	6.88
64.49	2.29	-1.88	8.54	9.39	6.96
64.58	2.29	-1.88	8.55	9.48	6.87
64.66	2.29	-1.89	8.55	9.47	6.88
64.74	2.30	-1.89	8.55	9.44	6.91
64.83	2.30	-1.89	8.55	9.44	6.91
64.91	2.30	-1.89	8.54	9.42	6.93
64.99	2.31	-1.90	8.55	9.50	6.85
65.08	2.31	-1.90	8.55	9.46	6.89
65.16	2.31	-1.90	8.55	9.45	6.90
65.24	2.31	-1.90	8.56	9.40	6.96
65.33	2.32	-1.90	8.56	9.46	6.89
65.41	2.32	-1.91	8.56	9.48	6.88
65.49	2.32	-1.91	8.55	9.48	6.87
65.58	2.33	-1.91	8.56	9.45	6.91
65.66	2.33	-1.91	8.56	9.47	6.88
65.74	2.33	-1.92	8.56	9.43	6.93
65.83	2.34	-1.92	8.56	9.47	6.88
65.91	2.34	-1.92	8.57	9.49	6.87
65.99	2.34	-1.92	8.57	9.49	6.87
66.08	2.34	-1.93	8.57	9.41	6.95
66.16	2.35	-1.93	8.57	9.49	6.87
66.24	2.35	-1.93	8.57	9.49	6.87
66.33	2.35	-1.93	8.57	9.50	6.86
66.41	2.36	-1.94	8.58	9.48	6.88
66.49	2.36	-1.94	8.56	9.42	6.93
66.58	2.36	-1.94	8.57	9.48	6.88
66.66	2.36	-1.94	8.59	9.45	6.91
66.74	2.37	-1.94	8.59	9.43	6.93
66.83	2.37	-1.95	8.58	9.49	6.88
66.91	2.37	-1.95	8.58	9.48	6.88
66.99	2.38	-1.95	8.59	9.48	6.89
67.08	2.38	-1.95	8.58	9.47	6.89
67.16	2.38	-1.96	8.58	9.41	6.95
67.24	2.39	-1.96	8.59	9.48	6.88
67.33	2.39	-1.96	8.59	9.51	6.85
67.41	2.39	-1.96	8.60	9.49	6.88
67.49	2.39	-1.97	8.60	9.50	6.86
67.58	2.40	-1.97	8.61	9.43	6.93
67.66	2.40	-1.97	8.60	9.50	6.87
67.74	2.40	-1.97	8.60	9.47	6.89
67.83	2.41	-1.97	8.60	9.46	6.91
67.91	2.41	-1.98	8.59	9.50	6.87
67.99	2.41	-1.98	8.61	9.49	6.88
68.08	2.42	-1.98	8.61	9.50	6.87
68.16	2.42	-1.98	8.61	9.49	6.88
68.24	2.42	-1.99	8.61	9.49	6.88
68.33	2.42	-1.99	8.61	9.42	6.95
68.41	2.43	-1.99	8.61	9.50	6.87
68.49	2.43	-1.99	8.59	9.51	6.86
68.58	2.43	-2.00	8.61	9.48	6.89
68.66	2.44	-2.00	8.62	9.49	6.88
68.74	2.44	-2.00	8.62	9.48	6.90
68.83	2.44	-2.00	8.62	9.54	6.83
68.91	2.44	-2.00	8.62	9.51	6.87
68.99	2.45	-2.01	8.63	9.49	6.88
69.08	2.45	-2.01	8.63	9.46	6.91
69.16	2.45	-2.01	8.62	9.51	6.86
69.24	2.46	-2.01	8.63	9.51	6.87
69.33	2.46	-2.02	8.64	9.49	6.89
69.41	2.46	-2.02	8.63	9.49	6.88
69.49	2.47	-2.02	8.63	9.50	6.87
69.58	2.47	-2.02	8.64	9.44	6.94
69.66	2.47	-2.03	8.63	9.50	6.87
69.74	2.47	-2.03	8.63	9.49	6.88
69.83	2.48	-2.03	8.64	9.51	6.87
69.91	2.48	-2.03	8.64	9.45	6.93
69.99	2.48	-2.03	8.64	9.50	6.88
70.08	2.49	-2.04	8.65	9.48	6.90
70.16	2.49	-2.04	8.65	9.49	6.89
70.24	2.49	-2.04	8.64	9.51	6.87
70.33	2.49	-2.04	8.66	9.44	6.95
70.41	2.50	-2.05	8.65	9.53	6.85
70.49	2.50	-2.05	8.66	9.50	6.88
70.58	2.50	-2.05	8.65	9.49	6.90
70.66	2.51	-2.05	8.65	9.53	6.85
70.74	2.51	-2.06	8.66	9.45	6.93
70.83	2.51	-2.06	8.66	9.52	6.87
70.91	2.52	-2.06	8.66	9.50	6.89
70.99	2.52	-2.06	8.67	9.51	6.88
71.08	2.52	-2.06	8.66	9.52	6.87
71.16	2.52	-2.07	8.67	9.52	6.87
71.24	2.53	-2.07	8.67	9.56	6.83
71.33	2.53	-2.07	8.66	9.52	6.86
71.41	2.53	-2.07	8.66	9.51	6.88
71.49	2.54	-2.08	8.67	9.53	6.86
71.58	2.54	-2.08	8.67	9.51	6.88
71.66	2.54	-2.08	8.67	9.49	6.91
71.74	2.55	-2.08	8.67	9.51	6.88
71.83	2.55	-2.09	8.66	9.52	6.87
71.91	2.55	-2.09	8.68	9.54	6.86
71.99	2.55	-2.09	8.68	9.52	6.88
72.08	2.56	-2.09	8.68	9.56	6.84
72.16	2.56	-2.09	8.68	9.46	6.93
72.24	2.56	-2.10	8.67	9.55	6.85
72.33	2.57	-2.10	8.68	9.52	6.87
72.41	2.57	-2.10	8.69	9.54	6.86
72.49	2.57	-2.10	8.69	9.51	6.89
72.58	2.57	-2.11	8.68	9.47	6.93
72.66	2.58	-2.11	8.69	9.55	6.84
72.74	2.58	-2.11	8.69	9.58	6.82
72.83	2.58	-2.11	8.69	9.47	6.93
72.91	2.59	-2.12	8.69	9.53	6.87
72.99	2.59	-2.12	8.68	9.52	6.87
73.08	2.59	-2.12	8.70	9.55	6.85
73.16	2.60	-2.12	8.69	9.55	6.85
73.24	2.60	-2.12	8.70	9.48	6.92
73.33	2.60	-2.13	8.70	9.55	6.85
73.41	2.60	-2.13	8.71	9.53	6.87
73.49	2.61	-2.13	8.71	9.54	6.87
73.58	2.61	-2.13	8.71	9.56	6.84
73.66	2.61	-2.14	8.70	9.55	6.85
73.74	2.62	-2.14	8.72	9.58	6.83
73.83	2.62	-2.14	8.70	9.54	6.86
73.91	2.62	-2.14	8.71	9.51	6.89
73.99	2.63	-2.14	8.72	9.51	6.89
74.08	2.63	-2.15	8.72	9.53	6.88
74.16	2.63	-2.15	8.73	9.58	6.83
74.24	2.63	-2.15	8.73	9.51	6.90
74.33	2.64	-2.15	8.73	9.56	6.85
74.41	2.64	-2.16	8.73	9.56	6.85
74.49	2.64	-2.16	8.73	9.54	6.87
74.58	2.65	-2.16	8.73	9.56	6.85
74.66	2.65	-2.16	8.73	9.57	6.84
74.74	2.65	-2.17	8.75	9.49	6.92
74.83	2.65	-2.17	8.73	9.56	6.85
74.91	2.66	-2.17	8.74	9.53	6.89
74.99	2.66	-2.17	8.75	9.51	6.90
75.08	2.66	-2.17	8.74	9.52	6.89
75.16	2.67	-2.18	8.75	9.55	6.87
75.24	2.67	-2.18	8.74	9.50	6.91
75.33	2.67	-2.18	8.74	9.59	6.83
75.41	2.68	-2.18	8.75	9.53	6.88
75.49	2.68	-2.19	8.75	9.49	6.93
75.58	2.68	-2.19	8.75	9.56	6.85
75.66	2.68	-2.19	8.75	9.55	6.87
75.74	2.69	-2.19	8.76	9.55	6.87
75.83	2.69	-2.20	8.76	9.52	6.90
75.91	2.69	-2.20	8.75	9.54	6.88
75.99	2.70	-2.20	8.76	9.51	6.91
76.08	2.70	-2.20	8.76	9.57	6.85
76.16	2.70	-2.20	8.78	9.53	6.89
76.24	2.70	-2.21	8.77	9.54	6.88
76.33	2.71	-2.21	8.78	9.58	6.85
76.41	2.71	-2.21	8.78	9.49	6.93
76.49	2.71	-2.21	8.78	9.56	6.86
76.58	2.72	-2.22	8.77	9.55	6.87
76.66	2.72	-2.22	8.78	9.54	6.88
76.74	2.72	-2.22	8.77	9.52	6.91
76.83	2.73	-2.22	8.77	9.59	6.83
76.91	2.73	-2.22	8.78	9.57	6.86
76.99	2.73	-2.23	8.79	9.61	6.82
77.08	2.73	-2.23	8.79	9.58	6.85
77.16	2.74	-2.23	8.79	9.50	6.93
77.24	2.74	-2.23	8.79	9.58	6.85
77.33	2.74	-2.24	8.79	9.57	6.86
77.41	2.75	-2.24	8.79	9.59	6.84
77.49	2.75	-2.24	8.80	9.54	6.90
77.58	2.75	-2.24	8.81	9.56	6.88
77.66	2.76	-2.25	8.81	9.61	6.82
77.74	2.76	-2.25	8.81	9.56	6.88
77.83	2.76	-2.25	8.81	9.55	6.89
77.91	2.76	-2.25	8.81	9.59	6.84
77.99	2.77	-2.25	8.81	9.51	6.93
78.08	2.77	-2.26	8.80	9.57	6.86
78.16	2.77	-2.26	8.80	9.60	6.83
78.24	2.78	-2.26	8.80	9.60	6.84
78.33	2.78	-2.26	8.79	9.59	6.84
78.41	2.78	-2.27	8.80	9.61	6.83
78.49	2.78	-2.27	8.81	9.56	6.88
78.58	2.79	-2.27	8.81	9.55	6.88
78.66	2.79	-2.27	8.81	9.63	6.81
78.74	2.79	-2.27	8.81	9.63	6.81
78.83	2.80	-2.28	8.81	9.55	6.88
78.91	2.80	-2.28	8.81	9.59	6.84
78.99	2.80	-2.28	8.81	9.58	6.86
79.08	2.81	-2.28	8.82	9.56	6.88
79.16	2.81	-2.29	8.82	9.57	6.87
79.24	2.81	-2.29	8.82	9.53	6.91
79.33	2.81	-2.29	8.82	9.60	6.84
79.41	2.82	-2.29	8.83	9.56	6.89
79.49	2.82	-2.29	8.82	9.58	6.86
79.58	2.82	-2.30	8.83	9.58	6.87
79.66	2.83	-2.30	8.82	9.58	6.86
79.74	2.83	-2.30	8.82	9.58	6.86
79.83	2.83	-2.30	8.83	9.59	6.85
79.91	2.83	-2.30	8.83	9.59	6.85
79.99	2.84	-2.31	8.82	9.56	6.88
80.08	2.84	-2.31	8.83	9.60	6.85
80.16	2.84	-2.31	8.84	9.54	6.90
80.24	2.85	-2.31	8.83	9.57	6.87
80.33	2.85	-2.32	8.83	9.56	6.88
80.41	2.85	-2.32	8.83	9.57	6.87
80.49	2.86	-2.32	8.84	9.57	6.88
80.58	2.86	-2.32	8.83	9.58	6.86
80.66	2.86	-2.32	8.84	9.57	6.88
80.74	2.86	-2.33	8.85	9.59	6.85
80.83	2.87	-2.33	8.84	9.60	6.85
80.91	2.87	-2.33	8.85	9.59	6.86
80.99	2.87	-2.33	8.84	9.60	6.85
81.08	2.88	-2.34	8.85	9.57	6.88
81.16	2.88	-2.34	8.85	9.58	6.87
81.24	2.88	-2.34	8.85	9.59	6.86
81.33	2.89	-2.34	8.85	9.60	6.85
81.41	2.89	-2.34	8.86	9.60	6.85
81.49	2.89	-2.35	8.87	9.58	6.88
81.58	2.89	-2.35	8.87	9.61	6.85
81.66	2.90	-2.35	8.87	9.61	6.84
81.74	2.90	-2.35	8.85	9.58	6.87
81.83	2.90	-2.35	8.87	9.59	6.86
81.91	2.91	-2.36	8.86	9.60	6.86
81.99	2.91	-2.36	8.87	9.58	6.87
82.08	2.91	-2.36	8.88	9.60	6.86
82.16	2.91	-2.36	8.88	9.61	6.85
82.24	2.92	-2.37	8.87	9.54	6.92
82.33	2.92	-2.37	8.87	9.61	6.85
82.41	2.92	-2.37	8.87	9.59	6.87
82.49	2.93	-2.37	8.88	9.58	6.88
82.58	2.93	-2.37	8.89	9.57	6.89
82.66	2.93	-2.38	8.88	9.62	6.85
82.74	2.94	-2.38	8.88	9.58	6.88
82.83	2.94	-2.38	8.88	9.60	6.86
82.91	2.94	-2.38	8.89	9.57	6.89
82.99	2.94	-2.39	8.88	9.63	6.83
83.08	2.95	-2.39	8.89	9.60	6.86
83.16	2.95	-2.39	8.90	9.59	6.87
83.24	2.95	-2.39	8.89	9.61	6.86
83.33	2.96	-2.39	8.89	9.62	6.85
83.41	2.96	-2.40	8.90	9.59	6.88
83.49	2.96	-2.40	8.91	9.59	6.88
83.58	2.97	-2.40	8.90	9.64	6.82
83.66	2.97	-2.40	8.91	9.62	6.85
83.74	2.97	-2.41	8.91	9.61	6.86
83.83	2.97	-2.41	8.91	9.61	6.86
83.91	2.98	-2.41	8.91	9.62	6.86
83.99	2.98	-2.41	8.91	9.62	6.85
84.08	2.98	-2.41	8.92	9.59	6.88
84.16	2.99	-2.42	8.92	9.60	6.87
84.24	2.99	-2.42	8.92	9.61	6.87
84.33	2.99	-2.42	8.92	9.59	6.88
84.41	2.99	-2.42	8.91	9.65	6.82
84.49	3.00	-2.42	8.91	9.62	6.85
84.58	3.00	-2.43	8.92	9.63	6.84
84.66	3.00	-2.43	8.92	9.63	6.84
84.74	3.01	-2.43	8.93	9.64	6.84
84.83	3.01	-2.43	8.93	9.63	6.85
84.91	3.01	-2.43	8.93	9.61	6.87
84.99	3.02	-2.44	8.93	9.60	6.88
85.08	3.02	-2.44	8.93	9.61	6.87
85.16	3.02	-2.44	8.93	9.60	6.88
85.24	3.02	-2.44	8.92	9.65	6.82
85.33	3.03	-2.45	8.94	9.61	6.87
85.41	3.03	-2.45	8.93	9.64	6.83
85.49	3.03	-2.45	8.93	9.65	6.82
85.58	3.04	-2.45	8.94	9.64	6.84
85.66	3.04	-2.45	8.94	9.65	6.83
85.74	3.04	-2.46	8.94	9.63	6.85
85.83	3.04	-2.46	8.95	9.60	6.88
85.91	3.05	-2.46	8.95	9.63	6.85
85.99	3.05	-2.46	8.95	9.63	6.85
86.08	3.05	-2.46	8.95	9.61	6.87
86.16	3.06	-2.47	8.95	9.64	6.84
86.24	3.06	-2.47	8.96	9.58	6.91
86.33	3.06	-2.47	8.96	9.64	6.85
86.41	3.07	-2.47	8.97	9.62	6.87
86.49	3.07	-2.48	8.96	9.64	6.84
86.58	3.07	-2.48	8.96	9.62	6.87
86.66	3.07	-2.48	8.96	9.64	6.84
86.74	3.08	-2.48	8.97	9.64	6.85
86.83	3.08	-2.48	8.96	9.64	6.85
86.91	3.08	-2.49	8.97	9.63	6.85
86.99	3.09	-2.49	8.97	9.63	6.86
87.08	3.09	-2.49	8.97	9.63	6.86
87.16	3.09	-2.49	8.98	9.63	6.86
87.24	3.10	-2.49	8.98	9.63	6.86
87.33	3.10	-2.50	8.98	9.64	6.85
87.41	3.10	-2.50	8.98	9.64	6.85
87.49	3.10	-2.50	8.99	9.65	6.85
87.58	3.11	-2.50	8.99	9.61	6.88
87.66	3.11	-2.51	8.98	9.67	6.83
87.74	3.11	-2.51	8.98	9.66	6.84
87.83	3.12	-2.51	8.99	9.65	6.85
87.91	3.12	-2.51	8.99	9.67	6.83
87.99	3.12	-2.51	9.00	9.63	6.87
88.08	3.12	-2.52	9.00	9.64	6.86
88.16	3.13	-2.52	9.00	9.63	6.87
88.24	3.13	-2.52	9.00	9.71	6.79
88.33	3.13	-2.52	9.01	9.67	6.84
88.41	3.14	-2.53	9.01	9.67	6.83
88.49	3.14	-2.53	9.01	9.61	6.89
88.58	3.14	-2.53	9.01	9.70	6.81
88.66	3.15	-2.53	9.01	9.67	6.83
88.74	3.15	-2.53	9.01	9.66	6.84
88.83	3.15	-2.54	9.01	9.66	6.84
88.91	3.15	-2.54	9.02	9.69	6.81
88.99	3.16	-2.54	9.01	9.59	6.91
89.08	3.16	-2.54	9.02	9.67	6.84
89.16	3.16	-2.54	9.02	9.67	6.84
89.24	3.17	-2.55	9.03	9.63	6.88
89.33	3.17	-2.55	9.03	9.61	6.90
89.41	3.17	-2.55	9.03	9.70	6.81
89.49	3.17	-2.55	9.03	9.67	6.84
89.58	3.18	-2.55	9.03	9.65	6.86
89.66	3.18	-2.56	9.03	9.69	6.82
89.74	3.18	-2.56	9.03	9.65	6.86
89.83	3.19	-2.56	9.04	9.66	6.85
89.91	3.19	-2.56	9.04	9.69	6.82
89.99	3.19	-2.56	9.04	9.72	6.80
90.08	3.20	-2.57	9.04	9.66	6.85
90.16	3.20	-2.57	9.04	9.64	6.87
90.24	3.20	-2.57	9.04	9.69	6.83
90.33	3.20	-2.57	9.05	9.69	6.83
90.41	3.21	-2.58	9.05	9.72	6.80
90.49	3.21	-2.58	9.05	9.65	6.87
90.58	3.21	-2.58	9.05	9.66	6.86
90.66	3.22	-2.58	9.05	9.64	6.88
90.74	3.22	-2.58	9.06	9.71	6.80
90.83	3.22	-2.59	9.06	9.69	6.83
90.91	3.23	-2.59	9.06	9.68	6.84
90.99	3.23	-2.59	9.07	9.69	6.84
91.08	3.23	-2.59	9.06	9.68	6.85
91.16	3.23	-2.59	9.07	9.65	6.88
91.24	3.24	-2.60	9.07	9.70	6.82
91.33	3.24	-2.60	9.07	9.66	6.86
91.41	3.24	-2.60	9.08	9.67	6.86
91.49	3.25	-2.60	9.07	9.70	6.82
91.58	3.25	-2.60	9.08	9.71	6.82
91.66	3.25	-2.61	9.08	9.71	6.82
91.74	3.25	-2.61	9.08	9.68	6.85
91.83	3.26	-2.61	9.08	9.71	6.81
91.91	3.26	-2.61	9.09	9.63	6.90
91.99	3.26	-2.61	9.09	9.71	6.82
92.08	3.27	-2.62	9.09	9.71	6.83
92.16	3.27	-2.62	9.10	9.67	6.87
92.24	3.27	-2.62	9.10	9.70	6.83
92.33	3.28	-2.62	9.10	9.71	6.83
92.41	3.28	-2.62	9.10	9.72	6.81
92.49	3.28	-2.63	9.10	9.72	6.82
92.58	3.28	-2.63	9.11	9.71	6.82
92.66	3.29	-2.63	9.11	9.63	6.91
92.74	3.29	-2.63	9.11	9.70	6.83
92.83	3.29	-2.64	9.11	9.71	6.83
92.91	3.30	-2.64	9.12	9.67	6.86
92.99	3.30	-2.64	9.12	9.68	6.86
93.08	3.30	-2.64	9.12	9.66	6.88
93.16	3.31	-2.64	9.12	9.73	6.81
93.24	3.31	-2.65	9.11	9.70	6.84
93.33	3.31	-2.65	9.13	9.68	6.86
93.41	3.31	-2.65	9.12	9.68	6.86
93.49	3.32	-2.65	9.13	9.68	6.87
93.58	3.32	-2.65	9.13	9.70	6.85
93.66	3.32	-2.66	9.13	9.71	6.84
93.74	3.33	-2.66	9.13	9.68	6.87
93.83	3.33	-2.66	9.14	9.67	6.88
93.91	3.33	-2.66	9.14	9.75	6.79
93.99	3.33	-2.66	9.14	9.72	6.83
94.08	3.34	-2.67	9.15	9.72	6.83
94.16	3.34	-2.67	9.14	9.73	6.81
94.24	3.34	-2.67	9.14	9.64	6.90
94.33	3.35	-2.67	9.15	9.76	6.79
94.41	3.35	-2.67	9.15	9.72	6.83
94.49	3.35	-2.68	9.15	9.70	6.85
94.58	3.36	-2.68	9.14	9.69	6.86
94.66	3.36	-2.68	9.15	9.71	6.85
94.74	3.36	-2.68	9.15	9.71	6.84
94.83	3.36	-2.68	9.16	9.72	6.84
94.91	3.37	-2.69	9.16	9.71	6.84
94.99	3.37	-2.69	9.16	9.68	6.87
95.08	3.37	-2.69	9.16	9.75	6.80
95.16	3.38	-2.69	9.16	9.71	6.84
95.24	3.38	-2.69	9.17	9.72	6.83
95.33	3.38	-2.70	9.16	9.72	6.83
95.41	3.38	-2.70	9.16	9.69	6.86
95.49	3.39	-2.70	9.17	9.77	6.79
95.58	3.39	-2.70	9.17	9.72	6.83
95.66	3.39	-2.70	9.18	9.72	6.84
95.74	3.40	-2.71	9.18	9.71	6.84
95.83	3.40	-2.71	9.17	9.71	6.85
95.91	3.40	-2.71	9.18	9.70	6.86
95.99	3.41	-2.71	9.18	9.75	6.81
96.08	3.41	-2.72	9.18	9.76	6.80
96.16	3.41	-2.72	9.19	9.70	6.87
96.24	3.41	-2.72	9.18	9.78	6.78
96.33	3.42	-2.72	9.19	9.75	6.81
96.41	3.42	-2.72	9.19	9.75	6.81
96.49	3.42	-2.73	9.19	9.74	6.82
96.58	3.43	-2.73	9.19	9.70	6.86
96.66	3.43	-2.73	9.19	9.76	6.80
96.74	3.43	-2.73	9.20	9.77	6.79
96.83	3.44	-2.73	9.19	9.71	6.85
96.91	3.44	-2.74	9.19	9.80	6.76
96.99	3.44	-2.74	9.20	9.77	6.80
97.08	3.44	-2.74	9.21	9.75	6.82
97.16	3.45	-2.74	9.20	9.77	6.80
97.24	3.45	-2.74	9.21	9.72	6.85
97.33	3.45	-2.75	9.20	9.70	6.87
97.41	3.46	-2.75	9.21	9.74	6.83
97.49	3.46	-2.75	9.21	9.70	6.87
97.58	3.46	-2.75	9.21	9.77	6.81
97.66	3.46	-2.75	9.21	9.75	6.83
97.74	3.47	-2.76	9.21	9.73	6.84
97.83	3.47	-2.76	9.21	9.72	6.85
97.91	3.47	-2.76	9.21	9.77	6.80
97.99	3.48	-2.76	9.22	9.76	6.81
98.08	3.48	-2.76	9.22	9.74	6.84
98.16	3.48	-2.77	9.22	9.77	6.81
98.24	3.49	-2.77	9.23	9.71	6.87
98.33	3.49	-2.77	9.23	9.78	6.80
98.41	3.49	-2.77	9.23	9.77	6.81
98.49	3.49	-2.77	9.23	9.74	6.83
98.58	3.50	-2.78	9.23	9.74	6.84
98.66	3.50	-2.78	9.23	9.78	6.80
98.74	3.50	-2.78	9.23	9.76	6.82
98.83	3.51	-2.78	9.24	9.73	6.85
98.91	3.51	-2.78	9.23	9.80	6.78
98.99	3.51	-2.78	9.22	9.79	6.78
99.08	3.51	-2.79	9.25	9.75	6.84
99.16	3.52	-2.79	9.24	9.75	6.83
99.24	3.52	-2.79	9.24	9.79	6.79
99.33	3.52	-2.79	9.25	9.74	6.84
99.41	3.53	-2.79	9.24	9.72	6.86
99.49	3.53	-2.80	9.23	9.79	6.79
99.58	3.53	-2.80	9.25	9.76	6.82
99.66	3.54	-2.80	9.24	9.78	6.80
99.74	3.54	-2.80	9.25	9.79	6.80
99.83	3.54	-2.80	9.25	9.79	6.80
99.91	3.54	-2.81	9.24	9.79	6.79
99.99	3.55	-2.81	9.26	9.72	6.87
100.08	3.55	-2.81	9.25	9.83	6.76
100.16	3.55	-2.81	9.25	9.80	6.78
100.24	3.56	-2.81	9.26	9.80	6.78
100.33	3.56	-2.82	9.26	9.78	6.81
100.41	3.56	-2.82	9.26	9.78	6.80
100.49	3.57	-2.82	9.26	9.80	6.79
100.58	3.57	-2.82	9.26	9.79	6.80
100.66	3.57	-2.82	9.26	9.74	6.85
100.74	3.57	-2.83	9.26	9.81	6.77
100.83	3.58	-2.83	9.25	9.83	6.76
100.91	3.58	-2.83	9.27	9.73	6.86
100.99	3.58	-2.83	9.24	9.83	6.74
101.08	3.59	-2.83	9.26	9.80	6.78
101.16	3.59	-2.84	9.26	9.82	6.77
101.24	3.59	-2.84	9.26	9.77	6.82
101.33	3.59	-2.84	9.24	9.81	6.77
101.41	3.60	-2.84	9.25	9.78	6.80
101.49	3.60	-2.84	9.24	9.78	6.80
101.58	3.60	-2.85	9.23	9.78	6.80
101.66	3.61	-2.85	9.21	9.78	6.79
101.74	3.61	-2.85	9.20	9.83	6.73
101.83	3.61	-2.85	9.20	9.81	6.76
101.91	3.62	-2.85	9.17	9.81	6.75
101.99	3.62	-2.85	9.18	9.80	6.76
102.08	3.62	-2.86	9.18	9.84	6.72
102.16	3.62	-2.86	9.17	9.81	6.75
102.24	3.63	-2.86	9.17	9.81	6.75
102.33	3.63	-2.86	9.15	9.83	6.72
102.41	3.63	-2.86	9.15	9.75	6.80
102.49	3.64	-2.86	9.13	9.87	6.67
102.58	3.64	-2.87	9.14	9.83	6.72
102.66	3.64	-2.87	9.13	9.87	6.68
102.74	3.64	-2.87	9.13	9.83	6.71
102.83	3.65	-2.87	9.12	9.77	6.77
102.91	3.65	-2.87	9.12	9.86	6.68
102.99	3.65	-2.87	9.12	9.84	6.70
103.08	3.66	-2.88	9.12	9.84	6.70
103.16	3.66	-2.88	9.12	9.84	6.70
103.24	3.66	-2.88	9.12	9.82	6.72
103.33	3.67	-2.88	9.11	9.87	6.67
103.41	3.67	-2.88	9.11	9.82	6.72
103.49	3.67	-2.88	9.11	9.83	6.71
103.58	3.67	-2.89	9.11	9.85	6.69
103.66	3.68	-2.89	9.12	9.84	6.70
103.74	3.68	-2.89	9.10	9.83	6.70
103.83	3.68	-2.89	9.11	9.86	6.67
103.91	3.69	-2.89	9.11	9.87	6.67
103.99	3.69	-2.90	9.11	9.87	6.66
104.08	3.69	-2.90	9.11	9.84	6.70
104.16	3.70	-2.90	9.12	9.82	6.72
104.24	3.70	-2.90	9.11	9.83	6.71
104.33	3.70	-2.90	9.11	9.87	6.67
104.41	3.70	-2.90	9.12	9.89	6.65
104.49	3.71	-2.91	9.10	9.86	6.68
104.58	3.71	-2.91	9.11	9.86	6.68
104.66	3.71	-2.91	9.10	9.86	6.68
104.74	3.72	-2.91	9.11	9.89	6.65
104.83	3.72	-2.91	9.11	9.84	6.70
104.91	3.72	-2.92	9.11	9.83	6.70
104.99	3.72	-2.92	9.11	9.84	6.69
105.08	3.73	-2.92	9.11	9.84	6.70
105.16	3.73	-2.92	9.10	9.85	6.68
105.24	3.73	-2.92	9.10	9.87	6.66
105.33	3.74	-2.92	9.10	9.85	6.68
105.41	3.74	-2.93	9.10	9.86	6.67
105.49	3.74	-2.93	9.10	9.88	6.65
105.58	3.75	-2.93	9.10	9.86	6.67
105.66	3.75	-2.93	9.10	9.87	6.66
105.74	3.75	-2.93	9.11	9.87	6.67
105.83	3.75	-2.93	9.10	9.84	6.69
105.91	3.76	-2.94	9.10	9.87	6.67
105.99	3.76	-2.94	9.11	9.87	6.67
106.08	3.76	-2.94	9.10	9.88	6.66
106.16	3.77	-2.94	9.10	9.87	6.67
106.24	3.77	-2.94	9.10	9.85	6.69
106.33	3.77	-2.95	9.09	9.88	6.65
106.41	3.78	-2.95	9.10	9.91	6.63
106.49	3.78	-2.95	9.10	9.84	6.70
106.58	3.78	-2.95	9.10	9.93	6.61
106.66	3.78	-2.95	9.09	9.91	6.61
106.74	3.79	-2.95	9.10	9.91	6.62
106.83	3.79	-2.96	9.10	9.85	6.68
106.91	3.79	-2.96	9.10	9.92	6.61
106.99	3.80	-2.96	9.10	9.92	6.62
107.08	3.80	-2.96	9.10	9.91	6.63
107.16	3.80	-2.96	9.10	9.90	6.63
107.24	3.80	-2.97	9.11	9.88	6.66
107.33	3.81	-2.97	9.10	9.90	6.63
107.41	3.81	-2.97	9.09	9.90	6.63
107.49	3.81	-2.97	9.10	9.89	6.65
107.58	3.82	-2.97	9.11	9.89	6.65
107.66	3.82	-2.97	9.11	9.96	6.58
107.74	3.82	-2.98	9.11	9.84	6.70
107.83	3.83	-2.98	9.11	9.91	6.62
107.91	3.83	-2.98	9.11	9.93	6.60
107.99	3.83	-2.98	9.11	9.90	6.63
108.08	3.83	-2.98	9.12	9.87	6.67
108.16	3.84	-2.99	9.10	9.92	6.61
108.24	3.84	-2.99	9.11	9.92	6.61
108.33	3.84	-2.99	9.11	9.91	6.63
108.41	3.85	-2.99	9.12	9.91	6.63
108.49	3.85	-2.99	9.12	9.89	6.65
108.58	3.85	-2.99	9.12	9.87	6.67
108.66	3.85	-3.00	9.11	9.93	6.60
108.74	3.86	-3.00	9.12	9.89	6.65
108.83	3.86	-3.00	9.11	9.96	6.58
108.91	3.86	-3.00	9.12	9.88	6.67
108.99	3.87	-3.00	9.13	9.87	6.67
109.08	3.87	-3.01	9.13	9.89	6.66
109.16	3.87	-3.01	9.12	9.89	6.65
109.24	3.88	-3.01	9.12	9.86	6.68
109.33	3.88	-3.01	9.12	9.93	6.61
109.41	3.88	-3.01	9.13	9.91	6.63
109.49	3.88	-3.01	9.13	9.89	6.65
109.58	3.89	-3.02	9.13	9.90	6.64
109.66	3.89	-3.02	9.13	9.90	6.65
109.74	3.89	-3.02	9.13	9.90	6.64
109.83	3.90	-3.02	9.13	9.93	6.61
109.91	3.90	-3.02	9.14	9.89	6.66
109.99	3.90	-3.03	9.13	9.95	6.60
110.08	3.91	-3.03	9.14	9.91	6.63
110.16	3.91	-3.03	9.14	9.89	6.66
110.24	3.91	-3.03	9.13	9.91	6.64
110.33	3.91	-3.03	9.14	9.91	6.64
110.41	3.92	-3.03	9.14	9.90	6.64
110.49	3.92	-3.04	9.14	9.90	6.65
110.58	3.92	-3.04	9.14	9.93	6.62
110.66	3.93	-3.04	9.14	9.94	6.60
110.74	3.93	-3.04	9.15	9.93	6.62
110.83	3.93	-3.04	9.14	9.92	6.62
110.91	3.93	-3.05	9.15	9.92	6.63
110.99	3.94	-3.05	9.15	9.93	6.61
111.08	3.94	-3.05	9.15	9.94	6.60
111.16	3.94	-3.05	9.15	9.92	6.64
111.24	3.95	-3.05	9.15	9.92	6.63
111.33	3.95	-3.05	9.16	9.92	6.64
111.41	3.95	-3.06	9.16	9.91	6.64
111.49	3.96	-3.06	9.16	9.93	6.63
111.58	3.96	-3.06	9.16	9.94	6.61
111.66	3.96	-3.06	9.16	9.92	6.63
111.74	3.96	-3.06	9.16	9.89	6.67
111.83	3.97	-3.07	9.17	9.92	6.63
111.91	3.97	-3.07	9.17	9.93	6.63
111.99	3.97	-3.07	9.17	9.94	6.62
112.08	3.98	-3.07	9.17	9.95	6.61
112.16	3.98	-3.07	9.17	9.94	6.61
112.24	3.98	-3.07	9.17	9.93	6.62
112.33	3.98	-3.08	9.16	9.95	6.61
112.41	3.99	-3.08	9.17	9.93	6.62
112.49	3.99	-3.08	9.17	9.93	6.63
112.58	3.99	-3.08	9.17	9.93	6.62
112.66	4.00	-3.08	9.17	9.93	6.63
112.74	4.00	-3.09	9.17	9.92	6.63
112.83	4.00	-3.09	9.17	9.89	6.67
112.91	4.01	-3.09	9.17	9.96	6.59
112.99	4.01	-3.09	9.17	9.95	6.60
113.08	4.01	-3.09	9.17	9.97	6.58
113.16	4.01	-3.09	9.18	9.93	6.62
113.24	4.02	-3.10	9.17	9.93	6.63
113.33	4.02	-3.10	9.17	9.93	6.63
113.41	4.02	-3.10	9.18	9.92	6.64
113.49	4.03	-3.10	9.18	9.93	6.63
113.58	4.03	-3.10	9.18	9.94	6.61
113.66	4.03	-3.11	9.17	9.95	6.61
113.74	4.04	-3.11	9.18	9.93	6.63
113.83	4.04	-3.11	9.18	9.92	6.64
113.91	4.04	-3.11	9.19	9.93	6.64
113.99	4.04	-3.11	9.18	9.94	6.62
114.08	4.05	-3.12	9.17	9.94	6.62
114.16	4.05	-3.12	9.19	9.95	6.61
114.24	4.05	-3.12	9.19	9.96	6.60
114.33	4.06	-3.12	9.19	9.95	6.61
114.41	4.06	-3.12	9.18	9.94	6.62
114.49	4.06	-3.12	9.19	9.93	6.64
114.58	4.06	-3.13	9.19	9.95	6.61
114.66	4.07	-3.13	9.19	9.93	6.63
114.74	4.07	-3.13	9.19	9.98	6.59
114.83	4.07	-3.13	9.20	9.95	6.61
114.91	4.08	-3.13	9.20	9.95	6.62
114.99	4.08	-3.14	9.19	9.95	6.61
115.08	4.08	-3.14	9.20	9.98	6.59
115.16	4.09	-3.14	9.20	9.98	6.59
115.24	4.09	-3.14	9.19	9.95	6.62
115.33	4.09	-3.14	9.21	9.96	6.60
115.41	4.09	-3.15	9.20	9.97	6.59
115.49	4.10	-3.15	9.21	9.98	6.59
115.58	4.10	-3.15	9.21	9.95	6.62
115.66	4.10	-3.15	9.21	9.95	6.62
115.74	4.11	-3.15	9.22	9.97	6.60
115.83	4.11	-3.15	9.21	9.96	6.62
115.91	4.11	-3.16	9.21	9.95	6.62
115.99	4.12	-3.16	9.22	9.97	6.60
116.08	4.12	-3.16	9.21	9.96	6.61
116.16	4.12	-3.16	9.21	9.95	6.62
116.24	4.12	-3.16	9.21	9.96	6.61
116.33	4.13	-3.17	9.22	9.96	6.61
116.41	4.13	-3.17	9.21	10.02	6.55
116.49	4.13	-3.17	9.22	10.02	6.55
116.58	4.14	-3.17	9.22	9.95	6.62
116.66	4.14	-3.17	9.22	9.97	6.60
116.74	4.14	-3.18	9.23	9.96	6.62
116.83	4.14	-3.18	9.23	9.97	6.61
116.91	4.15	-3.18	9.23	9.97	6.60
116.99	4.15	-3.18	9.23	9.99	6.59
117.08	4.15	-3.18	9.22	9.98	6.60
117.16	4.16	-3.18	9.22	9.98	6.59
117.24	4.16	-3.19	9.23	9.97	6.60
117.33	4.16	-3.19	9.24	9.98	6.60
117.41	4.17	-3.19	9.23	9.97	6.60
117.49	4.17	-3.19	9.24	9.98	6.60
117.58	4.17	-3.19	9.23	9.99	6.58
117.66	4.17	-3.20	9.23	10.00	6.58
117.74	4.18	-3.20	9.24	10.00	6.58
117.83	4.18	-3.20	9.25	9.99	6.59
117.91	4.18	-3.20	9.23	9.98	6.60
117.99	4.19	-3.20	9.24	9.98	6.60
118.08	4.19	-3.20	9.24	9.98	6.60
118.16	4.19	-3.21	9.24	9.99	6.59
118.24	4.19	-3.21	9.25	9.96	6.62
118.33	4.20	-3.21	9.25	10.04	6.55
118.41	4.20	-3.21	9.25	10.01	6.58
118.49	4.20	-3.21	9.26	9.99	6.60
118.58	4.21	-3.22	9.26	10.00	6.58
118.66	4.21	-3.22	9.25	10.03	6.56
118.74	4.21	-3.22	9.26	10.00	6.58
118.83	4.22	-3.22	9.26	10.03	6.56
118.84	4.22	-3.22	9.15	13.25	3.30